Workbook

Sheet Referensi
A1: PROVINSI | C1: : | D1: Kalimantan Selatan
A2: DAERAH | C2: : | D2: Kab. Hulu Sungai Selatan
A3: NO | C3: :
A4: TAHUN | C4: : | D4: 2026
A6: NO RUAS | D6: NAMA RUAS JALAN | E6: KECAMATAN YANG DILALUI | F6: PANJANG RUAS (Km) | G6: LEBAR RUAS (M) | H6: JENIS PERKERASAN (KM) | M6: PANJANG TIAP KONDISI | U6: LHR | V6: AKSES KE N/P/K | W6: KET
H7: HOTMIX | I7: Lapen / Makadam | J7: Perkerasan Beton | K7: Telford/ Kerikil | L7: Tanah/ Belum Tembus | M7: BAIK | O7: SEDANG | Q7: RUSAK RINGAN | S7: RUSAK BERAT
M8: KM | N8: % | O8: KM | P8: % | Q8: KM | R8: % | S8: KM | T8: %
A9: 0 | B9: 0 | C9: 1 | D9: Jl. Pangeran Antasari - Loklua | E9: Kandangan | F9: 0.56 | G9: 12 | H9: 0.56 | I9: 0 | J9: 0 | K9: 0 | L9: 0 | M9: 0 | N9: 0 | O9: 0.36000001 | P9: 0.64285717 | Q9: 0.2 | R9: 0.35714286 | S9: 0 | T9: 0 | U9: 0 | V9: 0 | W9: 2025
A10: 0 | B10: 0 | C10: 2 | D10: Jl. Soeprapto - Jl. H.M Rusli | E10: Kandangan | F10: 0.52 | G10: 6 | H10: 0.51999998 | I10: 0 | J10: 0 | K10: 0 | L10: 0 | M10: 0 | N10: 0 | O10: 0.51999998 | P10: 0.99999996 | Q10: 0 | R10: 0 | S10: 0 | T10: 0 | U10: 0 | V10: 0 | W10: 2025
A11: 0 | B11: 0 | C11: 3 | D11: Jl. Pasar Kandangan - Oprit Jembt. Loklua | E11: Kandangan | F11: 0.28 | G11: 6 | H11: 0 | I11: 0 | J11: 0.28 | K11: 0 | L11: 0 | M11: 0.28 | N11: 1 | O11: 0 | P11: 0 | Q11: 0 | R11: 0 | S11: 0 | T11: 0 | U11: 0 | V11: 0 | W11: 2025
A12: 0 | B12: 0 | C12: 4 | D12: Jl. Soetoyo - Teluk Mesjid | E12: Kandangan | F12: 0.26 | G12: 5 | H12: 0.25999999 | I12: 0 | J12: 0 | K12: 0 | L12: 0 | M12: 0.25999999 | N12: 0.99999996 | O12: 0 | P12: 0 | Q12: 0 | R12: 0 | S12: 0 | T12: 0 | U12: 0 | V12: 0 | W12: 2025
A13: 0 | B13: 0 | C13: 5 | D13: Jl. Teluk Mesjid - Sp. 4 Muara Banta | E13: Kandangan | F13: 1.43 | G13: 5 | H13: 1.4299999 | I13: 0 | J13: 0 | K13: 0 | L13: 0 | M13: 0 | N13: 0 | O13: 1.23 | P13: 0.86013987 | Q13: 0.2 | R13: 0.13986014 | S13: 0 | T13: 0 | U13: 0 | V13: 0 | W13: 2025
A14: 0 | B14: 0 | C14: 6 | D14: Jl. Merah Johansyah - Jl. Melati | E14: Kandangan | F14: 0.82 | G14: 6 | H14: 0.81999999 | I14: 0 | J14: 0 | K14: 0 | L14: 0 | M14: 0.81999999 | N14: 0.99999999 | O14: 0 | P14: 0 | Q14: 0 | R14: 0 | S14: 0 | T14: 0 | U14: 0 | V14: 0 | W14: 2025
A15: 0 | B15: 0 | C15: 7 | D15: Jl. Menuju Stadion 2 Desember | E15: Kandangan | F15: 0.29 | G15: 12 | H15: 0.28999999 | I15: 0 | J15: 0 | K15: 0 | L15: 0 | M15: 0 | N15: 0 | O15: 0.28999999 | P15: 0.99999997 | Q15: 0 | R15: 0 | S15: 0 | T15: 0 | U15: 0 | V15: 0 | W15: 2025
A16: 0 | B16: 0 | C16: 8 | D16: Jl. Aluh Idut | E16: Kandangan | F16: 1.34 | G16: 5 | H16: 1.34 | I16: 0 | J16: 0 | K16: 0 | L16: 0 | M16: 0.5 | N16: 0.37313433 | O16: 0.83999997 | P16: 0.62686565 | Q16: 0 | R16: 0 | S16: 0 | T16: 0 | U16: 0 | V16: 0 | W16: 2025
A17: 0 | B17: 0 | C17: 9 | D17: Jl. Panglima Batur | E17: Kandangan | F17: 1.09 | G17: 5 | H17: 1.09 | I17: 0 | J17: 0 | K17: 0 | L17: 0 | M17: 0.80000001 | N17: 0.73394497 | O17: 0.28999999 | P17: 0.26605504 | Q17: 0 | R17: 0 | S17: 0 | T17: 0 | U17: 0 | V17: 0 | W17: 2025
A18: 0 | B18: 1 | C18: 0 | D18: Jl. Nusa Indah | E18: Kandangan | F18: 0.38 | G18: 5 | H18: 0.38 | I18: 0 | J18: 0 | K18: 0 | L18: 0 | M18: 0.2 | N18: 0.5263158 | O18: 0.18000001 | P18: 0.47368423 | Q18: 0 | R18: 0 | S18: 0 | T18: 0 | U18: 0 | V18: 0 | W18: 2025
A19: 0 | B19: 1 | C19: 1 | D19: Jl. Anggrek | E19: Kandangan | F19: 0.23 | G19: 3 | H19: 0.23 | I19: 0 | J19: 0 | K19: 0 | L19: 0 | M19: 0.23 | N19: 1 | O19: 0 | P19: 0 | Q19: 0 | R19: 0 | S19: 0 | T19: 0 | U19: 0 | V19: 0 | W19: 2025
A20: 0 | B20: 1 | C20: 2 | D20: Jl. Kenanga | E20: Kandangan | F20: 0.23 | G20: 3 | H20: 0.23 | I20: 0 | J20: 0 | K20: 0 | L20: 0 | M20: 0.23 | N20: 1 | O20: 0 | P20: 0 | Q20: 0 | R20: 0 | S20: 0 | T20: 0 | U20: 0 | V20: 0 | W20: 2025
... A358: 3 | B358: 5 | C358: 0 | D358: Jl. Keramat Sakti - Ds. Tebing Tinggi | E358: Simpur | F358: 0.69 | G358: 3 | H358: 0.60000002 | I358: 0 | J358: 0 | K358: 0 | L358: 0.090000004 | M358: 0.2 | N358: 0.28985508 | O358: 0.40000001 | P358: 0.57971015 | Q358: 0 | R358: 0 | S358: 0.090000004 | T358: 0.13043479 | U358: 0 | V358: 0 | W358: 2025

Sheet Data_Analitik
A1: NO | B1: NO RUAS | C1: NAMA RUAS JALAN | D1: KECAMATAN | E1: PANJANG (KM) | F1: LEBAR (M) | G1: LHR | H1: AKSES N/P/K | I1: TAHUN DATA | J1: HOTMIX (KM) | K1: LAPEN/MAKADAM (KM) | L1: BETON (KM) | M1: TELFORD/KERIKIL (KM) | N1: TANAH/BELUM TEMBUS (KM) | O1: BAIK (KM) | P1: BAIK (%) | Q1: SEDANG (KM) | R1: SEDANG (%) | S1: RUSAK RINGAN (KM) | T1: RUSAK RINGAN (%) | U1: RUSAK BERAT (KM) | V1: RUSAK BERAT (%) | W1: MANTAP (KM) | X1: MANTAP (%) | Y1: TIDAK MANTAP (KM) | Z1: TIDAK MANTAP (%) | AA1: SKOR KERUSAKAN | AB1: KATEGORI KONDISI | AC1: METRIK AKTIF | AD1: LOLOS FILTER | AE1: URUTAN FILTER | AF1: COCOK KEC. DASHBOARD | AG1: PANJANG KEC. DASHBOARD | AH1: MANTAP KM KEC. DASHBOARD | AI1: TIDAK MANTAP KM KEC. DASHBOARD | AJ1: RUSAK BERAT KM KEC. DASHBOARD | AK1: COCOK KEC. ANALITIK | AL1: URUT KEC. ANALITIK | AM1: PANJANG KEC. ANALITIK | AN1: MANTAP KM KEC. ANALITIK | AO1: TIDAK MANTAP KM KEC. ANALITIK | AP1: RUSAK BERAT KM KEC. ANALITIK
A2: 1 | B2: 001 | C2: Jl. Pangeran Antasari - Loklua | D2: Kandangan | E2: 0.56 | F2: 12 | G2: 0 | I2: 2025 | J2: 0.56 | K2: 0 | L2: 0 | M2: 0 | N2: 0 | O2: 0 | P2: 0 | Q2: 0.36000001 | R2: 0.64285717 | S2: 0.2 | T2: 0.35714286 | U2: 0 | V2: 0 | W2: =O2+Q2 -> 0.36000001 | X2: =IFERROR(W2/E2,0) -> 0.64285717 | Y2: =S2+U2 -> 0.2 | Z2: =IFERROR(Y2/E2,0) -> 0.35714286 | AA2: =0.25*R2+0.6*T2+V2 -> 0.37500001 | AB2: =IF(V2>=0.2,"Rusak Berat Dominan",IF(Z2>=0.5,"Tidak Mantap Tinggi",IF(Z2>=0.2,"Tidak Mantap Sedang","Relatif Mantap"))) -> Tidak Mantap Sedang | AC2: =IF(Dashboard!$B$7="Mantap (%)",X2,IF(Dashboard!$B$7="Tidak Mantap (%)",Z2,IF(Dashboard!$B$7="Baik (%)",P2,IF(Dashboard!$B$7="Sedang (%)",R2,IF(Dashboard!$B$7="Rusak Ringan (%)",T2,IF(Dashboard!$B$7="Rusak Berat (%)",V2,AA2)))))) -> 0.35714286 | AD2: =IF(AND(AF2=1,E2>=Dashboard!$B$10,IF(Dashboard!$B$9="≤ Maksimum",AC2<=Dashboard!$B$8,AC2>=Dashboard!$B$8)),1,0) -> 1 | AE2: =IF(AD2=1,COUNTIFS($AD$2:$AD$351,1,$AC$2:$AC$351,">"&AC2)+COUNTIFS($AD$2:AD2,1,$AC$2:AC2,AC2),"") -> 158 | AF2: =IF(OR(Dashboard!$B$6="Semua",ISNUMBER(SEARCH(Dashboard!$B$6,D2))),1,0) -> 1 | AG2: =AF2*E2 -> 0.56 | AH2: =AF2*W2 -> 0.36000001 | AI2: =AF2*Y2 -> 0.2 | AJ2: =AF2*U2 -> 0 | AK2: =IF(OR(Ruas_Per_Kecamatan!$B$4="Semua",ISNUMBER(SEARCH(Ruas_Per_Kecamatan!$B$4,D2))),1,0) -> 1 | AL2: =IF(AK2=1,COUNTIF($AK$2:AK2,1),"") -> 1 | AM2: =AK2*E2 -> 0.56 | AN2: =AK2*W2 -> 0.36000001 | AO2: =AK2*Y2 -> 0.2 | AP2: =AK2*U2 -> 0
A3: 2 | B3: 002 | C3: Jl. Soeprapto - Jl. H.M Rusli | D3: Kandangan | E3: 0.52 | F3: 6 | G3: 0 | I3: 2025 | J3: 0.51999998 | K3: 0 | L3: 0 | M3: 0 | N3: 0 | O3: 0 | P3: 0 | Q3: 0.51999998 | R3: 0.99999996 | S3: 0 | T3: 0 | U3: 0 | V3: 0 | W3: =O3+Q3 -> 0.51999998 | X3: =IFERROR(W3/E3,0) -> 0.99999996 | Y3: =S3+U3 -> 0 | Z3: =IFERROR(Y3/E3,0) -> 0 | AA3: =0.25*R3+0.6*T3+V3 -> 0.24999999 | AB3: =IF(V3>=0.2,"Rusak Berat Dominan",IF(Z3>=0.5,"Tidak Mantap Tinggi",IF(Z3>=0.2,"Tidak Mantap Sedang","Relatif Mantap"))) -> Relatif Mantap | AC3: =IF(Dashboard!$B$7="Mantap (%)",X3,IF(Dashboard!$B$7="Tidak Mantap (%)",Z3,IF(Dashboard!$B$7="Baik (%)",P3,IF(Dashboard!$B$7="Sedang (%)",R3,IF(Dashboard!$B$7="Rusak Ringan (%)",T3,IF(Dashboard!$B$7="Rusak Berat (%)",V3,AA3)))))) -> 0 | AD3: =IF(AND(AF3=1,E3>=Dashboard!$B$10,IF(Dashboard!$B$9="≤ Maksimum",AC3<=Dashboard!$B$8,AC3>=Dashboard!$B$8)),1,0) -> 0 | AE3: =IF(AD3=1,COUNTIFS($AD$2:$AD$351,1,$AC$2:$AC$351,">"&AC3)+COUNTIFS($AD$2:AD3,1,$AC$2:AC3,AC3),"") | AF3: =IF(OR(Dashboard!$B$6="Semua",ISNUMBER(SEARCH(Dashboard!$B$6,D3))),1,0) -> 1 | AG3: =AF3*E3 -> 0.52 | AH3: =AF3*W3 -> 0.51999998 | AI3: =AF3*Y3 -> 0 | AJ3: =AF3*U3 -> 0 | AK3: =IF(OR(Ruas_Per_Kecamatan!$B$4="Semua",ISNUMBER(SEARCH(Ruas_Per_Kecamatan!$B$4,D3))),1,0) -> 1 | AL3: =IF(AK3=1,COUNTIF($AK$2:AK3,1),"") -> 2 | AM3: =AK3*E3 -> 0.52 | AN3: =AK3*W3 -> 0.51999998 | AO3: =AK3*Y3 -> 0 | AP3: =AK3*U3 -> 0
A4: 3 | B4: 003 | C4: Jl. Pasar Kandangan - Oprit Jembt. Loklua | D4: Kandangan | E4: 0.28 | F4: 6 | G4: 0 | I4: 2025 | J4: 0 | K4: 0 | L4: 0.28 | M4: 0 | N4: 0 | O4: 0.28 | P4: 1 | Q4: 0 | R4: 0 | S4: 0 | T4: 0 | U4: 0 | V4: 0 | W4: =O4+Q4 -> 0.28 | X4: =IFERROR(W4/E4,0) -> 1 | Y4: =S4+U4 -> 0 | Z4: =IFERROR(Y4/E4,0) -> 0 | AA4: =0.25*R4+0.6*T4+V4 -> 0 | AB4: =IF(V4>=0.2,"Rusak Berat Dominan",IF(Z4>=0.5,"Tidak Mantap Tinggi",IF(Z4>=0.2,"Tidak Mantap Sedang","Relatif Mantap"))) -> Relatif Mantap | AC4: =IF(Dashboard!$B$7="Mantap (%)",X4,IF(Dashboard!$B$7="Tidak Mantap (%)",Z4,IF(Dashboard!$B$7="Baik (%)",P4,IF(Dashboard!$B$7="Sedang (%)",R4,IF(Dashboard!$B$7="Rusak Ringan (%)",T4,IF(Dashboard!$B$7="Rusak Berat (%)",V4,AA4)))))) -> 0 | AD4: =IF(AND(AF4=1,E4>=Dashboard!$B$10,IF(Dashboard!$B$9="≤ Maksimum",AC4<=Dashboard!$B$8,AC4>=Dashboard!$B$8)),1,0) -> 0 | AE4: =IF(AD4=1,COUNTIFS($AD$2:$AD$351,1,$AC$2:$AC$351,">"&AC4)+COUNTIFS($AD$2:AD4,1,$AC$2:AC4,AC4),"") | AF4: =IF(OR(Dashboard!$B$6="Semua",ISNUMBER(SEARCH(Dashboard!$B$6,D4))),1,0) -> 1 | AG4: =AF4*E4 -> 0.28 | AH4: =AF4*W4 -> 0.28 | AI4: =AF4*Y4 -> 0 | AJ4: =AF4*U4 -> 0 | AK4: =IF(OR(Ruas_Per_Kecamatan!$B$4="Semua",ISNUMBER(SEARCH(Ruas_Per_Kecamatan!$B$4,D4))),1,0) -> 1 | AL4: =IF(AK4=1,COUNTIF($AK$2:AK4,1),"") -> 3 | AM4: =AK4*E4 -> 0.28 | AN4: =AK4*W4 -> 0.28 | AO4: =AK4*Y4 -> 0 | AP4: =AK4*U4 -> 0
A5: 4 | B5: 004 | C5: Jl. Soetoyo - Teluk Mesjid | D5: Kandangan | E5: 0.26 | F5: 5 | G5: 0 | I5: 2025 | J5: 0.25999999 | K5: 0 | L5: 0 | M5: 0 | N5: 0 | O5: 0.25999999 | P5: 0.99999996 | Q5: 0 | R5: 0 | S5: 0 | T5: 0 | U5: 0 | V5: 0 | W5: =O5+Q5 -> 0.25999999 | X5: =IFERROR(W5/E5,0) -> 0.99999996 | Y5: =S5+U5 -> 0 | Z5: =IFERROR(Y5/E5,0) -> 0 | AA5: =0.25*R5+0.6*T5+V5 -> 0 | AB5: =IF(V5>=0.2,"Rusak Berat Dominan",IF(Z5>=0.5,"Tidak Mantap Tinggi",IF(Z5>=0.2,"Tidak Mantap Sedang","Relatif Mantap"))) -> Relatif Mantap | AC5: =IF(Dashboard!$B$7="Mantap (%)",X5,IF(Dashboard!$B$7="Tidak Mantap (%)",Z5,IF(Dashboard!$B$7="Baik (%)",P5,IF(Dashboard!$B$7="Sedang (%)",R5,IF(Dashboard!$B$7="Rusak Ringan (%)",T5,IF(Dashboard!$B$7="Rusak Berat (%)",V5,AA5)))))) -> 0 | AD5: =IF(AND(AF5=1,E5>=Dashboard!$B$10,IF(Dashboard!$B$9="≤ Maksimum",AC5<=Dashboard!$B$8,AC5>=Dashboard!$B$8)),1,0) -> 0 | AE5: =IF(AD5=1,COUNTIFS($AD$2:$AD$351,1,$AC$2:$AC$351,">"&AC5)+COUNTIFS($AD$2:AD5,1,$AC$2:AC5,AC5),"") | AF5: =IF(OR(Dashboard!$B$6="Semua",ISNUMBER(SEARCH(Dashboard!$B$6,D5))),1,0) -> 1 | AG5: =AF5*E5 -> 0.26 | AH5: =AF5*W5 -> 0.25999999 | AI5: =AF5*Y5 -> 0 | AJ5: =AF5*U5 -> 0 | AK5: =IF(OR(Ruas_Per_Kecamatan!$B$4="Semua",ISNUMBER(SEARCH(Ruas_Per_Kecamatan!$B$4,D5))),1,0) -> 1 | AL5: =IF(AK5=1,COUNTIF($AK$2:AK5,1),"") -> 4 | AM5: =AK5*E5 -> 0.26 | AN5: =AK5*W5 -> 0.25999999 | AO5: =AK5*Y5 -> 0 | AP5: =AK5*U5 -> 0
A6: 5 | B6: 005 | C6: Jl. Teluk Mesjid - Sp. 4 Muara Banta | D6: Kandangan | E6: 1.43 | F6: 5 | G6: 0 | I6: 2025 | J6: 1.4299999 | K6: 0 | L6: 0 | M6: 0 | N6: 0 | O6: 0 | P6: 0 | Q6: 1.23 | R6: 0.86013987 | S6: 0.2 | T6: 0.13986014 | U6: 0 | V6: 0 | W6: =O6+Q6 -> 1.23 | X6: =IFERROR(W6/E6,0) -> 0.86013987 | Y6: =S6+U6 -> 0.2 | Z6: =IFERROR(Y6/E6,0) -> 0.13986014 | AA6: =0.25*R6+0.6*T6+V6 -> 0.29895105 | AB6: =IF(V6>=0.2,"Rusak Berat Dominan",IF(Z6>=0.5,"Tidak Mantap Tinggi",IF(Z6>=0.2,"Tidak Mantap Sedang","Relatif Mantap"))) -> Relatif Mantap | AC6: =IF(Dashboard!$B$7="Mantap (%)",X6,IF(Dashboard!$B$7="Tidak Mantap (%)",Z6,IF(Dashboard!$B$7="Baik (%)",P6,IF(Dashboard!$B$7="Sedang (%)",R6,IF(Dashboard!$B$7="Rusak Ringan (%)",T6,IF(Dashboard!$B$7="Rusak Berat (%)",V6,AA6)))))) -> 0.13986014 | AD6: =IF(AND(AF6=1,E6>=Dashboard!$B$10,IF(Dashboard!$B$9="≤ Maksimum",AC6<=Dashboard!$B$8,AC6>=Dashboard!$B$8)),1,0) -> 0 | AE6: =IF(AD6=1,COUNTIFS($AD$2:$AD$351,1,$AC$2:$AC$351,">"&AC6)+COUNTIFS($AD$2:AD6,1,$AC$2:AC6,AC6),"") | AF6: =IF(OR(Dashboard!$B$6="Semua",ISNUMBER(SEARCH(Dashboard!$B$6,D6))),1,0) -> 1 | AG6: =AF6*E6 -> 1.43 | AH6: =AF6*W6 -> 1.23 | AI6: =AF6*Y6 -> 0.2 | AJ6: =AF6*U6 -> 0 | AK6: =IF(OR(Ruas_Per_Kecamatan!$B$4="Semua",ISNUMBER(SEARCH(Ruas_Per_Kecamatan!$B$4,D6))),1,0) -> 1 | AL6: =IF(AK6=1,COUNTIF($AK$2:AK6,1),"") -> 5 | AM6: =AK6*E6 -> 1.43 | AN6: =AK6*W6 -> 1.23 | AO6: =AK6*Y6 -> 0.2 | AP6: =AK6*U6 -> 0
A7: 6 | B7: 006 | C7: Jl. Merah Johansyah - Jl. Melati | D7: Kandangan | E7: 0.82 | F7: 6 | G7: 0 | I7: 2025 | J7: 0.81999999 | K7: 0 | L7: 0 | M7: 0 | N7: 0 | O7: 0.81999999 | P7: 0.99999999 | Q7: 0 | R7: 0 | S7: 0 | T7: 0 | U7: 0 | V7: 0 | W7: =O7+Q7 -> 0.81999999 | X7: =IFERROR(W7/E7,0) -> 0.99999999 | Y7: =S7+U7 -> 0 | Z7: =IFERROR(Y7/E7,0) -> 0 | AA7: =0.25*R7+0.6*T7+V7 -> 0 | AB7: =IF(V7>=0.2,"Rusak Berat Dominan",IF(Z7>=0.5,"Tidak Mantap Tinggi",IF(Z7>=0.2,"Tidak Mantap Sedang","Relatif Mantap"))) -> Relatif Mantap | AC7: =IF(Dashboard!$B$7="Mantap (%)",X7,IF(Dashboard!$B$7="Tidak Mantap (%)",Z7,IF(Dashboard!$B$7="Baik (%)",P7,IF(Dashboard!$B$7="Sedang (%)",R7,IF(Dashboard!$B$7="Rusak Ringan (%)",T7,IF(Dashboard!$B$7="Rusak Berat (%)",V7,AA7)))))) -> 0 | AD7: =IF(AND(AF7=1,E7>=Dashboard!$B$10,IF(Dashboard!$B$9="≤ Maksimum",AC7<=Dashboard!$B$8,AC7>=Dashboard!$B$8)),1,0) -> 0 | AE7: =IF(AD7=1,COUNTIFS($AD$2:$AD$351,1,$AC$2:$AC$351,">"&AC7)+COUNTIFS($AD$2:AD7,1,$AC$2:AC7,AC7),"") | AF7: =IF(OR(Dashboard!$B$6="Semua",ISNUMBER(SEARCH(Dashboard!$B$6,D7))),1,0) -> 1 | AG7: =AF7*E7 -> 0.82 | AH7: =AF7*W7 -> 0.81999999 | AI7: =AF7*Y7 -> 0 | AJ7: =AF7*U7 -> 0 | AK7: =IF(OR(Ruas_Per_Kecamatan!$B$4="Semua",ISNUMBER(SEARCH(Ruas_Per_Kecamatan!$B$4,D7))),1,0) -> 1 | AL7: =IF(AK7=1,COUNTIF($AK$2:AK7,1),"") -> 6 | AM7: =AK7*E7 -> 0.82 | AN7: =AK7*W7 -> 0.81999999 | AO7: =AK7*Y7 -> 0 | AP7: =AK7*U7 -> 0
A8: 7 | B8: 007 | C8: Jl. Menuju Stadion 2 Desember | D8: Kandangan | E8: 0.29 | F8: 12 | G8: 0 | I8: 2025 | J8: 0.28999999 | K8: 0 | L8: 0 | M8: 0 | N8: 0 | O8: 0 | P8: 0 | Q8: 0.28999999 | R8: 0.99999997 | S8: 0 | T8: 0 | U8: 0 | V8: 0 | W8: =O8+Q8 -> 0.28999999 | X8: =IFERROR(W8/E8,0) -> 0.99999997 | Y8: =S8+U8 -> 0 | Z8: =IFERROR(Y8/E8,0) -> 0 | AA8: =0.25*R8+0.6*T8+V8 -> 0.24999999 | AB8: =IF(V8>=0.2,"Rusak Berat Dominan",IF(Z8>=0.5,"Tidak Mantap Tinggi",IF(Z8>=0.2,"Tidak Mantap Sedang","Relatif Mantap"))) -> Relatif Mantap | AC8: =IF(Dashboard!$B$7="Mantap (%)",X8,IF(Dashboard!$B$7="Tidak Mantap (%)",Z8,IF(Dashboard!$B$7="Baik (%)",P8,IF(Dashboard!$B$7="Sedang (%)",R8,IF(Dashboard!$B$7="Rusak Ringan (%)",T8,IF(Dashboard!$B$7="Rusak Berat (%)",V8,AA8)))))) -> 0 | AD8: =IF(AND(AF8=1,E8>=Dashboard!$B$10,IF(Dashboard!$B$9="≤ Maksimum",AC8<=Dashboard!$B$8,AC8>=Dashboard!$B$8)),1,0) -> 0 | AE8: =IF(AD8=1,COUNTIFS($AD$2:$AD$351,1,$AC$2:$AC$351,">"&AC8)+COUNTIFS($AD$2:AD8,1,$AC$2:AC8,AC8),"") | AF8: =IF(OR(Dashboard!$B$6="Semua",ISNUMBER(SEARCH(Dashboard!$B$6,D8))),1,0) -> 1 | AG8: =AF8*E8 -> 0.29 | AH8: =AF8*W8 -> 0.28999999 | AI8: =AF8*Y8 -> 0 | AJ8: =AF8*U8 -> 0 | AK8: =IF(OR(Ruas_Per_Kecamatan!$B$4="Semua",ISNUMBER(SEARCH(Ruas_Per_Kecamatan!$B$4,D8))),1,0) -> 1 | AL8: =IF(AK8=1,COUNTIF($AK$2:AK8,1),"") -> 7 | AM8: =AK8*E8 -> 0.29 | AN8: =AK8*W8 -> 0.28999999 | AO8: =AK8*Y8 -> 0 | AP8: =AK8*U8 -> 0
A9: 8 | B9: 008 | C9: Jl. Aluh Idut | D9: Kandangan | E9: 1.34 | F9: 5 | G9: 0 | I9: 2025 | J9: 1.34 | K9: 0 | L9: 0 | M9: 0 | N9: 0 | O9: 0.5 | P9: 0.37313433 | Q9: 0.83999997 | R9: 0.62686565 | S9: 0 | T9: 0 | U9: 0 | V9: 0 | W9: =O9+Q9 -> 1.34 | X9: =IFERROR(W9/E9,0) -> 0.99999998 | Y9: =S9+U9 -> 0 | Z9: =IFERROR(Y9/E9,0) -> 0 | AA9: =0.25*R9+0.6*T9+V9 -> 0.15671641 | AB9: =IF(V9>=0.2,"Rusak Berat Dominan",IF(Z9>=0.5,"Tidak Mantap Tinggi",IF(Z9>=0.2,"Tidak Mantap Sedang","Relatif Mantap"))) -> Relatif Mantap | AC9: =IF(Dashboard!$B$7="Mantap (%)",X9,IF(Dashboard!$B$7="Tidak Mantap (%)",Z9,IF(Dashboard!$B$7="Baik (%)",P9,IF(Dashboard!$B$7="Sedang (%)",R9,IF(Dashboard!$B$7="Rusak Ringan (%)",T9,IF(Dashboard!$B$7="Rusak Berat (%)",V9,AA9)))))) -> 0 | AD9: =IF(AND(AF9=1,E9>=Dashboard!$B$10,IF(Dashboard!$B$9="≤ Maksimum",AC9<=Dashboard!$B$8,AC9>=Dashboard!$B$8)),1,0) -> 0 | AE9: =IF(AD9=1,COUNTIFS($AD$2:$AD$351,1,$AC$2:$AC$351,">"&AC9)+COUNTIFS($AD$2:AD9,1,$AC$2:AC9,AC9),"") | AF9: =IF(OR(Dashboard!$B$6="Semua",ISNUMBER(SEARCH(Dashboard!$B$6,D9))),1,0) -> 1 | AG9: =AF9*E9 -> 1.34 | AH9: =AF9*W9 -> 1.34 | AI9: =AF9*Y9 -> 0 | AJ9: =AF9*U9 -> 0 | AK9: =IF(OR(Ruas_Per_Kecamatan!$B$4="Semua",ISNUMBER(SEARCH(Ruas_Per_Kecamatan!$B$4,D9))),1,0) -> 1 | AL9: =IF(AK9=1,COUNTIF($AK$2:AK9,1),"") -> 8 | AM9: =AK9*E9 -> 1.34 | AN9: =AK9*W9 -> 1.34 | AO9: =AK9*Y9 -> 0 | AP9: =AK9*U9 -> 0
A10: 9 | B10: 009 | C10: Jl. Panglima Batur | D10: Kandangan | E10: 1.09 | F10: 5 | G10: 0 | I10: 2025 | J10: 1.09 | K10: 0 | L10: 0 | M10: 0 | N10: 0 | O10: 0.80000001 | P10: 0.73394497 | Q10: 0.28999999 | R10: 0.26605504 | S10: 0 | T10: 0 | U10: 0 | V10: 0 | W10: =O10+Q10 -> 1.09 | X10: =IFERROR(W10/E10,0) -> 1 | Y10: =S10+U10 -> 0 | Z10: =IFERROR(Y10/E10,0) -> 0 | AA10: =0.25*R10+0.6*T10+V10 -> 0.06651376 | AB10: =IF(V10>=0.2,"Rusak Berat Dominan",IF(Z10>=0.5,"Tidak Mantap Tinggi",IF(Z10>=0.2,"Tidak Mantap Sedang","Relatif Mantap"))) -> Relatif Mantap | AC10: =IF(Dashboard!$B$7="Mantap (%)",X10,IF(Dashboard!$B$7="Tidak Mantap (%)",Z10,IF(Dashboard!$B$7="Baik (%)",P10,IF(Dashboard!$B$7="Sedang (%)",R10,IF(Dashboard!$B$7="Rusak Ringan (%)",T10,IF(Dashboard!$B$7="Rusak Berat (%)",V10,AA10)))))) -> 0 | AD10: =IF(AND(AF10=1,E10>=Dashboard!$B$10,IF(Dashboard!$B$9="≤ Maksimum",AC10<=Dashboard!$B$8,AC10>=Dashboard!$B$8)),1,0) -> 0 | AE10: =IF(AD10=1,COUNTIFS($AD$2:$AD$351,1,$AC$2:$AC$351,">"&AC10)+COUNTIFS($AD$2:AD10,1,$AC$2:AC10,AC10),"") | AF10: =IF(OR(Dashboard!$B$6="Semua",ISNUMBER(SEARCH(Dashboard!$B$6,D10))),1,0) -> 1 | AG10: =AF10*E10 -> 1.09 | AH10: =AF10*W10 -> 1.09 | AI10: =AF10*Y10 -> 0 | AJ10: =AF10*U10 -> 0 | AK10: =IF(OR(Ruas_Per_Kecamatan!$B$4="Semua",ISNUMBER(SEARCH(Ruas_Per_Kecamatan!$B$4,D10))),1,0) -> 1 | AL10: =IF(AK10=1,COUNTIF($AK$2:AK10,1),"") -> 9 | AM10: =AK10*E10 -> 1.09 | AN10: =AK10*W10 -> 1.09 | AO10: =AK10*Y10 -> 0 | AP10: =AK10*U10 -> 0
A11: 10 | B11: 010 | C11: Jl. Nusa Indah | D11: Kandangan | E11: 0.38 | F11: 5 | G11: 0 | I11: 2025 | J11: 0.38 | K11: 0 | L11: 0 | M11: 0 | N11: 0 | O11: 0.2 | P11: 0.5263158 | Q11: 0.18000001 | R11: 0.47368423 | S11: 0 | T11: 0 | U11: 0 | V11: 0 | W11: =O11+Q11 -> 0.38000001 | X11: =IFERROR(W11/E11,0) -> 1 | Y11: =S11+U11 -> 0 | Z11: =IFERROR(Y11/E11,0) -> 0 | AA11: =0.25*R11+0.6*T11+V11 -> 0.11842106 | AB11: =IF(V11>=0.2,"Rusak Berat Dominan",IF(Z11>=0.5,"Tidak Mantap Tinggi",IF(Z11>=0.2,"Tidak Mantap Sedang","Relatif Mantap"))) -> Relatif Mantap | AC11: =IF(Dashboard!$B$7="Mantap (%)",X11,IF(Dashboard!$B$7="Tidak Mantap (%)",Z11,IF(Dashboard!$B$7="Baik (%)",P11,IF(Dashboard!$B$7="Sedang (%)",R11,IF(Dashboard!$B$7="Rusak Ringan (%)",T11,IF(Dashboard!$B$7="Rusak Berat (%)",V11,AA11)))))) -> 0 | AD11: =IF(AND(AF11=1,E11>=Dashboard!$B$10,IF(Dashboard!$B$9="≤ Maksimum",AC11<=Dashboard!$B$8,AC11>=Dashboard!$B$8)),1,0) -> 0 | AE11: =IF(AD11=1,COUNTIFS($AD$2:$AD$351,1,$AC$2:$AC$351,">"&AC11)+COUNTIFS($AD$2:AD11,1,$AC$2:AC11,AC11),"") | AF11: =IF(OR(Dashboard!$B$6="Semua",ISNUMBER(SEARCH(Dashboard!$B$6,D11))),1,0) -> 1 | AG11: =AF11*E11 -> 0.38 | AH11: =AF11*W11 -> 0.38000001 | AI11: =AF11*Y11 -> 0 | AJ11: =AF11*U11 -> 0 | AK11: =IF(OR(Ruas_Per_Kecamatan!$B$4="Semua",ISNUMBER(SEARCH(Ruas_Per_Kecamatan!$B$4,D11))),1,0) -> 1 | AL11: =IF(AK11=1,COUNTIF($AK$2:AK11,1),"") -> 10 | AM11: =AK11*E11 -> 0.38 | AN11: =AK11*W11 -> 0.38000001 | AO11: =AK11*Y11 -> 0 | AP11: =AK11*U11 -> 0
A12: 11 | B12: 011 | C12: Jl. Anggrek | D12: Kandangan | E12: 0.23 | F12: 3 | G12: 0 | I12: 2025 | J12: 0.23 | K12: 0 | L12: 0 | M12: 0 | N12: 0 | O12: 0.23 | P12: 1 | Q12: 0 | R12: 0 | S12: 0 | T12: 0 | U12: 0 | V12: 0 | W12: =O12+Q12 -> 0.23 | X12: =IFERROR(W12/E12,0) -> 1 | Y12: =S12+U12 -> 0 | Z12: =IFERROR(Y12/E12,0) -> 0 | AA12: =0.25*R12+0.6*T12+V12 -> 0 | AB12: =IF(V12>=0.2,"Rusak Berat Dominan",IF(Z12>=0.5,"Tidak Mantap Tinggi",IF(Z12>=0.2,"Tidak Mantap Sedang","Relatif Mantap"))) -> Relatif Mantap | AC12: =IF(Dashboard!$B$7="Mantap (%)",X12,IF(Dashboard!$B$7="Tidak Mantap (%)",Z12,IF(Dashboard!$B$7="Baik (%)",P12,IF(Dashboard!$B$7="Sedang (%)",R12,IF(Dashboard!$B$7="Rusak Ringan (%)",T12,IF(Dashboard!$B$7="Rusak Berat (%)",V12,AA12)))))) -> 0 | AD12: =IF(AND(AF12=1,E12>=Dashboard!$B$10,IF(Dashboard!$B$9="≤ Maksimum",AC12<=Dashboard!$B$8,AC12>=Dashboard!$B$8)),1,0) -> 0 | AE12: =IF(AD12=1,COUNTIFS($AD$2:$AD$351,1,$AC$2:$AC$351,">"&AC12)+COUNTIFS($AD$2:AD12,1,$AC$2:AC12,AC12),"") | AF12: =IF(OR(Dashboard!$B$6="Semua",ISNUMBER(SEARCH(Dashboard!$B$6,D12))),1,0) -> 1 | AG12: =AF12*E12 -> 0.23 | AH12: =AF12*W12 -> 0.23 | AI12: =AF12*Y12 -> 0 | AJ12: =AF12*U12 -> 0 | AK12: =IF(OR(Ruas_Per_Kecamatan!$B$4="Semua",ISNUMBER(SEARCH(Ruas_Per_Kecamatan!$B$4,D12))),1,0) -> 1 | AL12: =IF(AK12=1,COUNTIF($AK$2:AK12,1),"") -> 11 | AM12: =AK12*E12 -> 0.23 | AN12: =AK12*W12 -> 0.23 | AO12: =AK12*Y12 -> 0 | AP12: =AK12*U12 -> 0
A13: 12 | B13: 012 | C13: Jl. Kenanga | D13: Kandangan | E13: 0.23 | F13: 3 | G13: 0 | I13: 2025 | J13: 0.23 | K13: 0 | L13: 0 | M13: 0 | N13: 0 | O13: 0.23 | P13: 1 | Q13: 0 | R13: 0 | S13: 0 | T13: 0 | U13: 0 | V13: 0 | W13: =O13+Q13 -> 0.23 | X13: =IFERROR(W13/E13,0) -> 1 | Y13: =S13+U13 -> 0 | Z13: =IFERROR(Y13/E13,0) -> 0 | AA13: =0.25*R13+0.6*T13+V13 -> 0 | AB13: =IF(V13>=0.2,"Rusak Berat Dominan",IF(Z13>=0.5,"Tidak Mantap Tinggi",IF(Z13>=0.2,"Tidak Mantap Sedang","Relatif Mantap"))) -> Relatif Mantap | AC13: =IF(Dashboard!$B$7="Mantap (%)",X13,IF(Dashboard!$B$7="Tidak Mantap (%)",Z13,IF(Dashboard!$B$7="Baik (%)",P13,IF(Dashboard!$B$7="Sedang (%)",R13,IF(Dashboard!$B$7="Rusak Ringan (%)",T13,IF(Dashboard!$B$7="Rusak Berat (%)",V13,AA13)))))) -> 0 | AD13: =IF(AND(AF13=1,E13>=Dashboard!$B$10,IF(Dashboard!$B$9="≤ Maksimum",AC13<=Dashboard!$B$8,AC13>=Dashboard!$B$8)),1,0) -> 0 | AE13: =IF(AD13=1,COUNTIFS($AD$2:$AD$351,1,$AC$2:$AC$351,">"&AC13)+COUNTIFS($AD$2:AD13,1,$AC$2:AC13,AC13),"") | AF13: =IF(OR(Dashboard!$B$6="Semua",ISNUMBER(SEARCH(Dashboard!$B$6,D13))),1,0) -> 1 | AG13: =AF13*E13 -> 0.23 | AH13: =AF13*W13 -> 0.23 | AI13: =AF13*Y13 -> 0 | AJ13: =AF13*U13 -> 0 | AK13: =IF(OR(Ruas_Per_Kecamatan!$B$4="Semua",ISNUMBER(SEARCH(Ruas_Per_Kecamatan!$B$4,D13))),1,0) -> 1 | AL13: =IF(AK13=1,COUNTIF($AK$2:AK13,1),"") -> 12 | AM13: =AK13*E13 -> 0.23 | AN13: =AK13*W13 -> 0.23 | AO13: =AK13*Y13 -> 0 | AP13: =AK13*U13 -> 0
... A351: 350 | B351: 350 | C351: Jl. Keramat Sakti - Ds. Tebing Tinggi | D351: Simpur | E351: 0.69 | F351: 3 | G351: 0 | I351: 2025 | J351: 0.60000002 | K351: 0 | L351: 0 | M351: 0 | N351: 0.090000004 | O351: 0.2 | P351: 0.28985508 | Q351: 0.40000001 | R351: 0.57971015 | S351: 0 | T351: 0 | U351: 0.090000004 | V351: 0.13043479 | W351: =O351+Q351 -> 0.60000001 | X351: =IFERROR(W351/E351,0) -> 0.86956523 | Y351: =S351+U351 -> 0.090000004 | Z351: =IFERROR(Y351/E351,0) -> 0.13043479 | AA351: =0.25*R351+0.6*T351+V351 -> 0.27536233 | AB351: =IF(V351>=0.2,"Rusak Berat Dominan",IF(Z351>=0.5,"Tidak Mantap Tinggi",IF(Z351>=0.2,"Tidak Mantap Sedang","Relatif Mantap"))) -> Relatif Mantap | AC351: =IF(Dashboard!$B$7="Mantap (%)",X351,IF(Dashboard!$B$7="Tidak Mantap (%)",Z351,IF(Dashboard!$B$7="Baik (%)",P351,IF(Dashboard!$B$7="Sedang (%)",R351,IF(Dashboard!$B$7="Rusak Ringan (%)",T351,IF(Dashboard!$B$7="Rusak Berat (%)",V351,AA351)))))) -> 0.13043479 | AD351: =IF(AND(AF351=1,E351>=Dashboard!$B$10,IF(Dashboard!$B$9="≤ Maksimum",AC351<=Dashboard!$B$8,AC351>=Dashboard!$B$8)),1,0) -> 0 | AE351: =IF(AD351=1,COUNTIFS($AD$2:$AD$351,1,$AC$2:$AC$351,">"&AC351)+COUNTIFS($AD$2:AD351,1,$AC$2:AC351,AC351),"") | AF351: =IF(OR(Dashboard!$B$6="Semua",ISNUMBER(SEARCH(Dashboard!$B$6,D351))),1,0) -> 1 | AG351: =AF351*E351 -> 0.69 | AH351: =AF351*W351 -> 0.60000001 | AI351: =AF351*Y351 -> 0.090000004 | AJ351: =AF351*U351 -> 0.090000004 | AK351: =IF(OR(Ruas_Per_Kecamatan!$B$4="Semua",ISNUMBER(SEARCH(Ruas_Per_Kecamatan!$B$4,D351))),1,0) -> 1 | AL351: =IF(AK351=1,COUNTIF($AK$2:AK351,1),"") -> 350 | AM351: =AK351*E351 -> 0.69 | AN351: =AK351*W351 -> 0.60000001 | AO351: =AK351*Y351 -> 0.090000004 | AP351: =AK351*U351 -> 0.090000004

Sheet Dashboard
A1: DASHBOARD ANALITIK KONDISI JALAN KABUPATEN HULU SUNGAI SELATAN
A3: Filter dapat diubah pada panel kiri; tabel prioritas dan KPI akan mengikuti secara otomatis.
A5: PANEL FILTER | D5: TOTAL RUAS | G5: TOTAL PANJANG | J5: KEMANTAPAN JARINGAN
A6: Kecamatan | B6: Semua | D6: =SUM(Data_Analitik!$AF$2:$AF$351) -> 350 | G6: =SUM(Data_Analitik!$AG$2:$AG$351) -> 732.46 | J6: =IFERROR(SUM(Data_Analitik!$AH$2:$AH$351)/SUM(Data_Analitik!$AG$2:$AG$351),0) -> 0.53639789
A7: Metrik threshold | B7: Tidak Mantap (%)
A8: Nilai threshold | B8: 0.2 | D8: TIDAK MANTAP | G8: RUSAK BERAT | J8: LOLOS THRESHOLD
A9: Arah threshold | B9: ≥ Minimum | D9: =SUM(Data_Analitik!$AI$2:$AI$351) -> 339.57 | G9: =SUM(Data_Analitik!$AJ$2:$AJ$351) -> 228.16 | J9: =SUM(Data_Analitik!$AD$2:$AD$351) -> 191
A10: Panjang minimum (km) | B10: 0
A11: Jumlah ruas ditampilkan | B11: 348
A12: DAFTAR RUAS PRIORITAS BERDASARKAN FILTER DAN THRESHOLD
A13: RANK | B13: NO RUAS | C13: NAMA RUAS | D13: KECAMATAN | E13: PANJANG (KM) | F13: TIDAK MANTAP (%) | G13: SKOR KERUSAKAN | H13: RUSAK BERAT (KM) | I13: KATEGORI
A14: =IF(ROW()-13<=$B$11,ROW()-13,"") -> 1 | B14: =IF(OR($A14="",$A14>SUM(Data_Analitik!$AD$2:$AD$351)),"",IFERROR(INDEX(Data_Analitik!$B$2:$B$351,MATCH($A14,Data_Analitik!$AE$2:$AE$351,0)),"")) -> 146 | C14: =IF(OR($A14="",$A14>SUM(Data_Analitik!$AD$2:$AD$351)),"",IFERROR(INDEX(Data_Analitik!$C$2:$C$351,MATCH($A14,Data_Analitik!$AE$2:$AE$351,0)),"")) -> Simpang Malutu - Pahampangan | D14: =IF(OR($A14="",$A14>SUM(Data_Analitik!$AD$2:$AD$351)),"",IFERROR(INDEX(Data_Analitik!$D$2:$D$351,MATCH($A14,Data_Analitik!$AE$2:$AE$351,0)),"")) -> Padang Batung - Sungai Raya | E14: =IF(OR($A14="",$A14>SUM(Data_Analitik!$AD$2:$AD$351)),"",IFERROR(INDEX(Data_Analitik!$E$2:$E$351,MATCH($A14,Data_Analitik!$AE$2:$AE$351,0)),"")) -> 4.51 | F14: =IF(OR($A14="",$A14>SUM(Data_Analitik!$AD$2:$AD$351)),"",IFERROR(INDEX(Data_Analitik!$Z$2:$Z$351,MATCH($A14,Data_Analitik!$AE$2:$AE$351,0)),"")) -> 1.0000001 | G14: =IF(OR($A14="",$A14>SUM(Data_Analitik!$AD$2:$AD$351)),"",IFERROR(INDEX(Data_Analitik!$AA$2:$AA$351,MATCH($A14,Data_Analitik!$AE$2:$AE$351,0)),"")) -> 1.0000001 | H14: =IF(OR($A14="",$A14>SUM(Data_Analitik!$AD$2:$AD$351)),"",IFERROR(INDEX(Data_Analitik!$U$2:$U$351,MATCH($A14,Data_Analitik!$AE$2:$AE$351,0)),"")) -> 4.5100002 | I14: =IF(OR($A14="",$A14>SUM(Data_Analitik!$AD$2:$AD$351)),"",IFERROR(INDEX(Data_Analitik!$AB$2:$AB$351,MATCH($A14,Data_Analitik!$AE$2:$AE$351,0)),"")) -> Rusak Berat Dominan
A15: =IF(ROW()-13<=$B$11,ROW()-13,"") -> 2 | B15: =IF(OR($A15="",$A15>SUM(Data_Analitik!$AD$2:$AD$351)),"",IFERROR(INDEX(Data_Analitik!$B$2:$B$351,MATCH($A15,Data_Analitik!$AE$2:$AE$351,0)),"")) -> 301 | C15: =IF(OR($A15="",$A15>SUM(Data_Analitik!$AD$2:$AD$351)),"",IFERROR(INDEX(Data_Analitik!$C$2:$C$351,MATCH($A15,Data_Analitik!$AE$2:$AE$351,0)),"")) -> Muning Tengah - Batang Alai (Pihanin Raya) | D15: =IF(OR($A15="",$A15>SUM(Data_Analitik!$AD$2:$AD$351)),"",IFERROR(INDEX(Data_Analitik!$D$2:$D$351,MATCH($A15,Data_Analitik!$AE$2:$AE$351,0)),"")) -> Daha Selatan | E15: =IF(OR($A15="",$A15>SUM(Data_Analitik!$AD$2:$AD$351)),"",IFERROR(INDEX(Data_Analitik!$E$2:$E$351,MATCH($A15,Data_Analitik!$AE$2:$AE$351,0)),"")) -> 5.26 | F15: =IF(OR($A15="",$A15>SUM(Data_Analitik!$AD$2:$AD$351)),"",IFERROR(INDEX(Data_Analitik!$Z$2:$Z$351,MATCH($A15,Data_Analitik!$AE$2:$AE$351,0)),"")) -> 1 | G15: =IF(OR($A15="",$A15>SUM(Data_Analitik!$AD$2:$AD$351)),"",IFERROR(INDEX(Data_Analitik!$AA$2:$AA$351,MATCH($A15,Data_Analitik!$AE$2:$AE$351,0)),"")) -> 1 | H15: =IF(OR($A15="",$A15>SUM(Data_Analitik!$AD$2:$AD$351)),"",IFERROR(INDEX(Data_Analitik!$U$2:$U$351,MATCH($A15,Data_Analitik!$AE$2:$AE$351,0)),"")) -> 5.2600002 | I15: =IF(OR($A15="",$A15>SUM(Data_Analitik!$AD$2:$AD$351)),"",IFERROR(INDEX(Data_Analitik!$AB$2:$AB$351,MATCH($A15,Data_Analitik!$AE$2:$AE$351,0)),"")) -> Rusak Berat Dominan
A16: =IF(ROW()-13<=$B$11,ROW()-13,"") -> 3 | B16: =IF(OR($A16="",$A16>SUM(Data_Analitik!$AD$2:$AD$351)),"",IFERROR(INDEX(Data_Analitik!$B$2:$B$351,MATCH($A16,Data_Analitik!$AE$2:$AE$351,0)),"")) -> 295 | C16: =IF(OR($A16="",$A16>SUM(Data_Analitik!$AD$2:$AD$351)),"",IFERROR(INDEX(Data_Analitik!$C$2:$C$351,MATCH($A16,Data_Analitik!$AE$2:$AE$351,0)),"")) -> Jl. Mawar | D16: =IF(OR($A16="",$A16>SUM(Data_Analitik!$AD$2:$AD$351)),"",IFERROR(INDEX(Data_Analitik!$D$2:$D$351,MATCH($A16,Data_Analitik!$AE$2:$AE$351,0)),"")) -> Daha Selatan | E16: =IF(OR($A16="",$A16>SUM(Data_Analitik!$AD$2:$AD$351)),"",IFERROR(INDEX(Data_Analitik!$E$2:$E$351,MATCH($A16,Data_Analitik!$AE$2:$AE$351,0)),"")) -> 0.27 | F16: =IF(OR($A16="",$A16>SUM(Data_Analitik!$AD$2:$AD$351)),"",IFERROR(INDEX(Data_Analitik!$Z$2:$Z$351,MATCH($A16,Data_Analitik!$AE$2:$AE$351,0)),"")) -> 1 | G16: =IF(OR($A16="",$A16>SUM(Data_Analitik!$AD$2:$AD$351)),"",IFERROR(INDEX(Data_Analitik!$AA$2:$AA$351,MATCH($A16,Data_Analitik!$AE$2:$AE$351,0)),"")) -> 0.60000002 | H16: =IF(OR($A16="",$A16>SUM(Data_Analitik!$AD$2:$AD$351)),"",IFERROR(INDEX(Data_Analitik!$U$2:$U$351,MATCH($A16,Data_Analitik!$AE$2:$AE$351,0)),"")) -> 0 | I16: =IF(OR($A16="",$A16>SUM(Data_Analitik!$AD$2:$AD$351)),"",IFERROR(INDEX(Data_Analitik!$AB$2:$AB$351,MATCH($A16,Data_Analitik!$AE$2:$AE$351,0)),"")) -> Tidak Mantap Tinggi
A17: =IF(ROW()-13<=$B$11,ROW()-13,"") -> 4 | B17: =IF(OR($A17="",$A17>SUM(Data_Analitik!$AD$2:$AD$351)),"",IFERROR(INDEX(Data_Analitik!$B$2:$B$351,MATCH($A17,Data_Analitik!$AE$2:$AE$351,0)),"")) -> 312 | C17: =IF(OR($A17="",$A17>SUM(Data_Analitik!$AD$2:$AD$351)),"",IFERROR(INDEX(Data_Analitik!$C$2:$C$351,MATCH($A17,Data_Analitik!$AE$2:$AE$351,0)),"")) -> Jl. Teluk Haur I | D17: =IF(OR($A17="",$A17>SUM(Data_Analitik!$AD$2:$AD$351)),"",IFERROR(INDEX(Data_Analitik!$D$2:$D$351,MATCH($A17,Data_Analitik!$AE$2:$AE$351,0)),"")) -> Daha Utara | E17: =IF(OR($A17="",$A17>SUM(Data_Analitik!$AD$2:$AD$351)),"",IFERROR(INDEX(Data_Analitik!$E$2:$E$351,MATCH($A17,Data_Analitik!$AE$2:$AE$351,0)),"")) -> 0.18 | F17: =IF(OR($A17="",$A17>SUM(Data_Analitik!$AD$2:$AD$351)),"",IFERROR(INDEX(Data_Analitik!$Z$2:$Z$351,MATCH($A17,Data_Analitik!$AE$2:$AE$351,0)),"")) -> 1 | G17: =IF(OR($A17="",$A17>SUM(Data_Analitik!$AD$2:$AD$351)),"",IFERROR(INDEX(Data_Analitik!$AA$2:$AA$351,MATCH($A17,Data_Analitik!$AE$2:$AE$351,0)),"")) -> 1 | H17: =IF(OR($A17="",$A17>SUM(Data_Analitik!$AD$2:$AD$351)),"",IFERROR(INDEX(Data_Analitik!$U$2:$U$351,MATCH($A17,Data_Analitik!$AE$2:$AE$351,0)),"")) -> 0.18000001 | I17: =IF(OR($A17="",$A17>SUM(Data_Analitik!$AD$2:$AD$351)),"",IFERROR(INDEX(Data_Analitik!$AB$2:$AB$351,MATCH($A17,Data_Analitik!$AE$2:$AE$351,0)),"")) -> Rusak Berat Dominan
A18: =IF(ROW()-13<=$B$11,ROW()-13,"") -> 5 | B18: =IF(OR($A18="",$A18>SUM(Data_Analitik!$AD$2:$AD$351)),"",IFERROR(INDEX(Data_Analitik!$B$2:$B$351,MATCH($A18,Data_Analitik!$AE$2:$AE$351,0)),"")) -> 332 | C18: =IF(OR($A18="",$A18>SUM(Data_Analitik!$AD$2:$AD$351)),"",IFERROR(INDEX(Data_Analitik!$C$2:$C$351,MATCH($A18,Data_Analitik!$AE$2:$AE$351,0)),"")) -> Jl. Kampung Kawat | D18: =IF(OR($A18="",$A18>SUM(Data_Analitik!$AD$2:$AD$351)),"",IFERROR(INDEX(Data_Analitik!$D$2:$D$351,MATCH($A18,Data_Analitik!$AE$2:$AE$351,0)),"")) -> Daha Utara | E18: =IF(OR($A18="",$A18>SUM(Data_Analitik!$AD$2:$AD$351)),"",IFERROR(INDEX(Data_Analitik!$E$2:$E$351,MATCH($A18,Data_Analitik!$AE$2:$AE$351,0)),"")) -> 0.33 | F18: =IF(OR($A18="",$A18>SUM(Data_Analitik!$AD$2:$AD$351)),"",IFERROR(INDEX(Data_Analitik!$Z$2:$Z$351,MATCH($A18,Data_Analitik!$AE$2:$AE$351,0)),"")) -> 1 | G18: =IF(OR($A18="",$A18>SUM(Data_Analitik!$AD$2:$AD$351)),"",IFERROR(INDEX(Data_Analitik!$AA$2:$AA$351,MATCH($A18,Data_Analitik!$AE$2:$AE$351,0)),"")) -> 1 | H18: =IF(OR($A18="",$A18>SUM(Data_Analitik!$AD$2:$AD$351)),"",IFERROR(INDEX(Data_Analitik!$U$2:$U$351,MATCH($A18,Data_Analitik!$AE$2:$AE$351,0)),"")) -> 0.33000001 | I18: =IF(OR($A18="",$A18>SUM(Data_Analitik!$AD$2:$AD$351)),"",IFERROR(INDEX(Data_Analitik!$AB$2:$AB$351,MATCH($A18,Data_Analitik!$AE$2:$AE$351,0)),"")) -> Rusak Berat Dominan
A19: =IF(ROW()-13<=$B$11,ROW()-13,"") -> 6 | B19: =IF(OR($A19="",$A19>SUM(Data_Analitik!$AD$2:$AD$351)),"",IFERROR(INDEX(Data_Analitik!$B$2:$B$351,MATCH($A19,Data_Analitik!$AE$2:$AE$351,0)),"")) -> 157 | C19: =IF(OR($A19="",$A19>SUM(Data_Analitik!$AD$2:$AD$351)),"",IFERROR(INDEX(Data_Analitik!$C$2:$C$351,MATCH($A19,Data_Analitik!$AE$2:$AE$351,0)),"")) -> Malilingin - Muara Hariang | D19: =IF(OR($A19="",$A19>SUM(Data_Analitik!$AD$2:$AD$351)),"",IFERROR(INDEX(Data_Analitik!$D$2:$D$351,MATCH($A19,Data_Analitik!$AE$2:$AE$351,0)),"")) -> Padang Batung | E19: =IF(OR($A19="",$A19>SUM(Data_Analitik!$AD$2:$AD$351)),"",IFERROR(INDEX(Data_Analitik!$E$2:$E$351,MATCH($A19,Data_Analitik!$AE$2:$AE$351,0)),"")) -> 4.57 | F19: =IF(OR($A19="",$A19>SUM(Data_Analitik!$AD$2:$AD$351)),"",IFERROR(INDEX(Data_Analitik!$Z$2:$Z$351,MATCH($A19,Data_Analitik!$AE$2:$AE$351,0)),"")) -> 1 | G19: =IF(OR($A19="",$A19>SUM(Data_Analitik!$AD$2:$AD$351)),"",IFERROR(INDEX(Data_Analitik!$AA$2:$AA$351,MATCH($A19,Data_Analitik!$AE$2:$AE$351,0)),"")) -> 1 | H19: =IF(OR($A19="",$A19>SUM(Data_Analitik!$AD$2:$AD$351)),"",IFERROR(INDEX(Data_Analitik!$U$2:$U$351,MATCH($A19,Data_Analitik!$AE$2:$AE$351,0)),"")) -> 4.5700002 | I19: =IF(OR($A19="",$A19>SUM(Data_Analitik!$AD$2:$AD$351)),"",IFERROR(INDEX(Data_Analitik!$AB$2:$AB$351,MATCH($A19,Data_Analitik!$AE$2:$AE$351,0)),"")) -> Rusak Berat Dominan
A20: =IF(ROW()-13<=$B$11,ROW()-13,"") -> 7 | B20: =IF(OR($A20="",$A20>SUM(Data_Analitik!$AD$2:$AD$351)),"",IFERROR(INDEX(Data_Analitik!$B$2:$B$351,MATCH($A20,Data_Analitik!$AE$2:$AE$351,0)),"")) -> 302 | C20: =IF(OR($A20="",$A20>SUM(Data_Analitik!$AD$2:$AD$351)),"",IFERROR(INDEX(Data_Analitik!$C$2:$C$351,MATCH($A20,Data_Analitik!$AE$2:$AE$351,0)),"")) -> Muning Tengah - Ds. Muning Dalam | D20: =IF(OR($A20="",$A20>SUM(Data_Analitik!$AD$2:$AD$351)),"",IFERROR(INDEX(Data_Analitik!$D$2:$D$351,MATCH($A20,Data_Analitik!$AE$2:$AE$351,0)),"")) -> Daha Selatan | E20: =IF(OR($A20="",$A20>SUM(Data_Analitik!$AD$2:$AD$351)),"",IFERROR(INDEX(Data_Analitik!$E$2:$E$351,MATCH($A20,Data_Analitik!$AE$2:$AE$351,0)),"")) -> 17.11 | F20: =IF(OR($A20="",$A20>SUM(Data_Analitik!$AD$2:$AD$351)),"",IFERROR(INDEX(Data_Analitik!$Z$2:$Z$351,MATCH($A20,Data_Analitik!$AE$2:$AE$351,0)),"")) -> 1 | G20: =IF(OR($A20="",$A20>SUM(Data_Analitik!$AD$2:$AD$351)),"",IFERROR(INDEX(Data_Analitik!$AA$2:$AA$351,MATCH($A20,Data_Analitik!$AE$2:$AE$351,0)),"")) -> 1 | H20: =IF(OR($A20="",$A20>SUM(Data_Analitik!$AD$2:$AD$351)),"",IFERROR(INDEX(Data_Analitik!$U$2:$U$351,MATCH($A20,Data_Analitik!$AE$2:$AE$351,0)),"")) -> 17.110001 | I20: =IF(OR($A20="",$A20>SUM(Data_Analitik!$AD$2:$AD$351)),"",IFERROR(INDEX(Data_Analitik!$AB$2:$AB$351,MATCH($A20,Data_Analitik!$AE$2:$AE$351,0)),"")) -> Rusak Berat Dominan
A21: =IF(ROW()-13<=$B$11,ROW()-13,"") -> 8 | B21: =IF(OR($A21="",$A21>SUM(Data_Analitik!$AD$2:$AD$351)),"",IFERROR(INDEX(Data_Analitik!$B$2:$B$351,MATCH($A21,Data_Analitik!$AE$2:$AE$351,0)),"")) -> 149 | C21: =IF(OR($A21="",$A21>SUM(Data_Analitik!$AD$2:$AD$351)),"",IFERROR(INDEX(Data_Analitik!$C$2:$C$351,MATCH($A21,Data_Analitik!$AE$2:$AE$351,0)),"")) -> Paku (Jambu Hulu) - Ganda | D21: =IF(OR($A21="",$A21>SUM(Data_Analitik!$AD$2:$AD$351)),"",IFERROR(INDEX(Data_Analitik!$D$2:$D$351,MATCH($A21,Data_Analitik!$AE$2:$AE$351,0)),"")) -> Padang Batung - Kandangan | E21: =IF(OR($A21="",$A21>SUM(Data_Analitik!$AD$2:$AD$351)),"",IFERROR(INDEX(Data_Analitik!$E$2:$E$351,MATCH($A21,Data_Analitik!$AE$2:$AE$351,0)),"")) -> 1.88 | F21: =IF(OR($A21="",$A21>SUM(Data_Analitik!$AD$2:$AD$351)),"",IFERROR(INDEX(Data_Analitik!$Z$2:$Z$351,MATCH($A21,Data_Analitik!$AE$2:$AE$351,0)),"")) -> 1 | G21: =IF(OR($A21="",$A21>SUM(Data_Analitik!$AD$2:$AD$351)),"",IFERROR(INDEX(Data_Analitik!$AA$2:$AA$351,MATCH($A21,Data_Analitik!$AE$2:$AE$351,0)),"")) -> 0.66382981 | H21: =IF(OR($A21="",$A21>SUM(Data_Analitik!$AD$2:$AD$351)),"",IFERROR(INDEX(Data_Analitik!$U$2:$U$351,MATCH($A21,Data_Analitik!$AE$2:$AE$351,0)),"")) -> 0.30000001 | I21: =IF(OR($A21="",$A21>SUM(Data_Analitik!$AD$2:$AD$351)),"",IFERROR(INDEX(Data_Analitik!$AB$2:$AB$351,MATCH($A21,Data_Analitik!$AE$2:$AE$351,0)),"")) -> Tidak Mantap Tinggi
A22: =IF(ROW()-13<=$B$11,ROW()-13,"") -> 9 | B22: =IF(OR($A22="",$A22>SUM(Data_Analitik!$AD$2:$AD$351)),"",IFERROR(INDEX(Data_Analitik!$B$2:$B$351,MATCH($A22,Data_Analitik!$AE$2:$AE$351,0)),"")) -> 112 | C22: =IF(OR($A22="",$A22>SUM(Data_Analitik!$AD$2:$AD$351)),"",IFERROR(INDEX(Data_Analitik!$C$2:$C$351,MATCH($A22,Data_Analitik!$AE$2:$AE$351,0)),"")) -> Jl. Bangga TMMD | D22: =IF(OR($A22="",$A22>SUM(Data_Analitik!$AD$2:$AD$351)),"",IFERROR(INDEX(Data_Analitik!$D$2:$D$351,MATCH($A22,Data_Analitik!$AE$2:$AE$351,0)),"")) -> Sungai Raya | E22: =IF(OR($A22="",$A22>SUM(Data_Analitik!$AD$2:$AD$351)),"",IFERROR(INDEX(Data_Analitik!$E$2:$E$351,MATCH($A22,Data_Analitik!$AE$2:$AE$351,0)),"")) -> 0.79 | F22: =IF(OR($A22="",$A22>SUM(Data_Analitik!$AD$2:$AD$351)),"",IFERROR(INDEX(Data_Analitik!$Z$2:$Z$351,MATCH($A22,Data_Analitik!$AE$2:$AE$351,0)),"")) -> 1 | G22: =IF(OR($A22="",$A22>SUM(Data_Analitik!$AD$2:$AD$351)),"",IFERROR(INDEX(Data_Analitik!$AA$2:$AA$351,MATCH($A22,Data_Analitik!$AE$2:$AE$351,0)),"")) -> 0.60000002 | H22: =IF(OR($A22="",$A22>SUM(Data_Analitik!$AD$2:$AD$351)),"",IFERROR(INDEX(Data_Analitik!$U$2:$U$351,MATCH($A22,Data_Analitik!$AE$2:$AE$351,0)),"")) -> 0 | I22: =IF(OR($A22="",$A22>SUM(Data_Analitik!$AD$2:$AD$351)),"",IFERROR(INDEX(Data_Analitik!$AB$2:$AB$351,MATCH($A22,Data_Analitik!$AE$2:$AE$351,0)),"")) -> Tidak Mantap Tinggi
A23: =IF(ROW()-13<=$B$11,ROW()-13,"") -> 10 | B23: =IF(OR($A23="",$A23>SUM(Data_Analitik!$AD$2:$AD$351)),"",IFERROR(INDEX(Data_Analitik!$B$2:$B$351,MATCH($A23,Data_Analitik!$AE$2:$AE$351,0)),"")) -> 155 | C23: =IF(OR($A23="",$A23>SUM(Data_Analitik!$AD$2:$AD$351)),"",IFERROR(INDEX(Data_Analitik!$C$2:$C$351,MATCH($A23,Data_Analitik!$AE$2:$AE$351,0)),"")) -> Muara Pipii - Tambak Pipii | D23: =IF(OR($A23="",$A23>SUM(Data_Analitik!$AD$2:$AD$351)),"",IFERROR(INDEX(Data_Analitik!$D$2:$D$351,MATCH($A23,Data_Analitik!$AE$2:$AE$351,0)),"")) -> Padang Batung | E23: =IF(OR($A23="",$A23>SUM(Data_Analitik!$AD$2:$AD$351)),"",IFERROR(INDEX(Data_Analitik!$E$2:$E$351,MATCH($A23,Data_Analitik!$AE$2:$AE$351,0)),"")) -> 4.65 | F23: =IF(OR($A23="",$A23>SUM(Data_Analitik!$AD$2:$AD$351)),"",IFERROR(INDEX(Data_Analitik!$Z$2:$Z$351,MATCH($A23,Data_Analitik!$AE$2:$AE$351,0)),"")) -> 1 | G23: =IF(OR($A23="",$A23>SUM(Data_Analitik!$AD$2:$AD$351)),"",IFERROR(INDEX(Data_Analitik!$AA$2:$AA$351,MATCH($A23,Data_Analitik!$AE$2:$AE$351,0)),"")) -> 0.96559142 | H23: =IF(OR($A23="",$A23>SUM(Data_Analitik!$AD$2:$AD$351)),"",IFERROR(INDEX(Data_Analitik!$U$2:$U$351,MATCH($A23,Data_Analitik!$AE$2:$AE$351,0)),"")) -> 4.2500001 | I23: =IF(OR($A23="",$A23>SUM(Data_Analitik!$AD$2:$AD$351)),"",IFERROR(INDEX(Data_Analitik!$AB$2:$AB$351,MATCH($A23,Data_Analitik!$AE$2:$AE$351,0)),"")) -> Rusak Berat Dominan
A24: =IF(ROW()-13<=$B$11,ROW()-13,"") -> 11 | B24: =IF(OR($A24="",$A24>SUM(Data_Analitik!$AD$2:$AD$351)),"",IFERROR(INDEX(Data_Analitik!$B$2:$B$351,MATCH($A24,Data_Analitik!$AE$2:$AE$351,0)),"")) -> 126 | C24: =IF(OR($A24="",$A24>SUM(Data_Analitik!$AD$2:$AD$351)),"",IFERROR(INDEX(Data_Analitik!$C$2:$C$351,MATCH($A24,Data_Analitik!$AE$2:$AE$351,0)),"")) -> Jl. Sungai Namang - Ds. Tanah Bangkang | D24: =IF(OR($A24="",$A24>SUM(Data_Analitik!$AD$2:$AD$351)),"",IFERROR(INDEX(Data_Analitik!$D$2:$D$351,MATCH($A24,Data_Analitik!$AE$2:$AE$351,0)),"")) -> Sungai Raya | E24: =IF(OR($A24="",$A24>SUM(Data_Analitik!$AD$2:$AD$351)),"",IFERROR(INDEX(Data_Analitik!$E$2:$E$351,MATCH($A24,Data_Analitik!$AE$2:$AE$351,0)),"")) -> 0.73 | F24: =IF(OR($A24="",$A24>SUM(Data_Analitik!$AD$2:$AD$351)),"",IFERROR(INDEX(Data_Analitik!$Z$2:$Z$351,MATCH($A24,Data_Analitik!$AE$2:$AE$351,0)),"")) -> 1 | G24: =IF(OR($A24="",$A24>SUM(Data_Analitik!$AD$2:$AD$351)),"",IFERROR(INDEX(Data_Analitik!$AA$2:$AA$351,MATCH($A24,Data_Analitik!$AE$2:$AE$351,0)),"")) -> 1 | H24: =IF(OR($A24="",$A24>SUM(Data_Analitik!$AD$2:$AD$351)),"",IFERROR(INDEX(Data_Analitik!$U$2:$U$351,MATCH($A24,Data_Analitik!$AE$2:$AE$351,0)),"")) -> 0.73000002 | I24: =IF(OR($A24="",$A24>SUM(Data_Analitik!$AD$2:$AD$351)),"",IFERROR(INDEX(Data_Analitik!$AB$2:$AB$351,MATCH($A24,Data_Analitik!$AE$2:$AE$351,0)),"")) -> Rusak Berat Dominan
A25: =IF(ROW()-13<=$B$11,ROW()-13,"") -> 12 | B25: =IF(OR($A25="",$A25>SUM(Data_Analitik!$AD$2:$AD$351)),"",IFERROR(INDEX(Data_Analitik!$B$2:$B$351,MATCH($A25,Data_Analitik!$AE$2:$AE$351,0)),"")) -> 256 | C25: =IF(OR($A25="",$A25>SUM(Data_Analitik!$AD$2:$AD$351)),"",IFERROR(INDEX(Data_Analitik!$C$2:$C$351,MATCH($A25,Data_Analitik!$AE$2:$AE$351,0)),"")) -> Balimau - Murung Dalam | D25: =IF(OR($A25="",$A25>SUM(Data_Analitik!$AD$2:$AD$351)),"",IFERROR(INDEX(Data_Analitik!$D$2:$D$351,MATCH($A25,Data_Analitik!$AE$2:$AE$351,0)),"")) -> Kalumpang | E25: =IF(OR($A25="",$A25>SUM(Data_Analitik!$AD$2:$AD$351)),"",IFERROR(INDEX(Data_Analitik!$E$2:$E$351,MATCH($A25,Data_Analitik!$AE$2:$AE$351,0)),"")) -> 1.46 | F25: =IF(OR($A25="",$A25>SUM(Data_Analitik!$AD$2:$AD$351)),"",IFERROR(INDEX(Data_Analitik!$Z$2:$Z$351,MATCH($A25,Data_Analitik!$AE$2:$AE$351,0)),"")) -> 1 | G25: =IF(OR($A25="",$A25>SUM(Data_Analitik!$AD$2:$AD$351)),"",IFERROR(INDEX(Data_Analitik!$AA$2:$AA$351,MATCH($A25,Data_Analitik!$AE$2:$AE$351,0)),"")) -> 1 | H25: =IF(OR($A25="",$A25>SUM(Data_Analitik!$AD$2:$AD$351)),"",IFERROR(INDEX(Data_Analitik!$U$2:$U$351,MATCH($A25,Data_Analitik!$AE$2:$AE$351,0)),"")) -> 1.46 | I25: =IF(OR($A25="",$A25>SUM(Data_Analitik!$AD$2:$AD$351)),"",IFERROR(INDEX(Data_Analitik!$AB$2:$AB$351,MATCH($A25,Data_Analitik!$AE$2:$AE$351,0)),"")) -> Rusak Berat Dominan
... A32: =IF(ROW()-13<=$B$11,ROW()-13,"") -> 19 | B32: =IF(OR($A32="",$A32>SUM(Data_Analitik!$AD$2:$AD$351)),"",IFERROR(INDEX(Data_Analitik!$B$2:$B$351,MATCH($A32,Data_Analitik!$AE$2:$AE$351,0)),"")) -> 348 | C32: =IF(OR($A32="",$A32>SUM(Data_Analitik!$AD$2:$AD$351)),"",IFERROR(INDEX(Data_Analitik!$C$2:$C$351,MATCH($A32,Data_Analitik!$AE$2:$AE$351,0)),"")) -> Jl. Asam Duhat - Ds. Pantai Ulin | D32: =IF(OR($A32="",$A32>SUM(Data_Analitik!$AD$2:$AD$351)),"",IFERROR(INDEX(Data_Analitik!$D$2:$D$351,MATCH($A32,Data_Analitik!$AE$2:$AE$351,0)),"")) -> Simpur | E32: =IF(OR($A32="",$A32>SUM(Data_Analitik!$AD$2:$AD$351)),"",IFERROR(INDEX(Data_Analitik!$E$2:$E$351,MATCH($A32,Data_Analitik!$AE$2:$AE$351,0)),"")) -> 1.11 | F32: =IF(OR($A32="",$A32>SUM(Data_Analitik!$AD$2:$AD$351)),"",IFERROR(INDEX(Data_Analitik!$Z$2:$Z$351,MATCH($A32,Data_Analitik!$AE$2:$AE$351,0)),"")) -> 1 | G32: =IF(OR($A32="",$A32>SUM(Data_Analitik!$AD$2:$AD$351)),"",IFERROR(INDEX(Data_Analitik!$AA$2:$AA$351,MATCH($A32,Data_Analitik!$AE$2:$AE$351,0)),"")) -> 1 | H32: =IF(OR($A32="",$A32>SUM(Data_Analitik!$AD$2:$AD$351)),"",IFERROR(INDEX(Data_Analitik!$U$2:$U$351,MATCH($A32,Data_Analitik!$AE$2:$AE$351,0)),"")) -> 1.11 | I32: =IF(OR($A32="",$A32>SUM(Data_Analitik!$AD$2:$AD$351)),"",IFERROR(INDEX(Data_Analitik!$AB$2:$AB$351,MATCH($A32,Data_Analitik!$AE$2:$AE$351,0)),"")) -> Rusak Berat Dominan
A33: =IF(ROW()-13<=$B$11,ROW()-13,"") -> 20 | B33: =IF(OR($A33="",$A33>SUM(Data_Analitik!$AD$2:$AD$351)),"",IFERROR(INDEX(Data_Analitik!$B$2:$B$351,MATCH($A33,Data_Analitik!$AE$2:$AE$351,0)),"")) -> 248 | C33: =IF(OR($A33="",$A33>SUM(Data_Analitik!$AD$2:$AD$351)),"",IFERROR(INDEX(Data_Analitik!$C$2:$C$351,MATCH($A33,Data_Analitik!$AE$2:$AE$351,0)),"")) -> Kalumpang (Ds. Balanti) - Teratai | D33: =IF(OR($A33="",$A33>SUM(Data_Analitik!$AD$2:$AD$351)),"",IFERROR(INDEX(Data_Analitik!$D$2:$D$351,MATCH($A33,Data_Analitik!$AE$2:$AE$351,0)),"")) -> Kalumpang | E33: =IF(OR($A33="",$A33>SUM(Data_Analitik!$AD$2:$AD$351)),"",IFERROR(INDEX(Data_Analitik!$E$2:$E$351,MATCH($A33,Data_Analitik!$AE$2:$AE$351,0)),"")) -> 5.69 | F33: =IF(OR($A33="",$A33>SUM(Data_Analitik!$AD$2:$AD$351)),"",IFERROR(INDEX(Data_Analitik!$Z$2:$Z$351,MATCH($A33,Data_Analitik!$AE$2:$AE$351,0)),"")) -> 1 | G33: =IF(OR($A33="",$A33>SUM(Data_Analitik!$AD$2:$AD$351)),"",IFERROR(INDEX(Data_Analitik!$AA$2:$AA$351,MATCH($A33,Data_Analitik!$AE$2:$AE$351,0)),"")) -> 1 | H33: =IF(OR($A33="",$A33>SUM(Data_Analitik!$AD$2:$AD$351)),"",IFERROR(INDEX(Data_Analitik!$U$2:$U$351,MATCH($A33,Data_Analitik!$AE$2:$AE$351,0)),"")) -> 5.6900001 | I33: =IF(OR($A33="",$A33>SUM(Data_Analitik!$AD$2:$AD$351)),"",IFERROR(INDEX(Data_Analitik!$AB$2:$AB$351,MATCH($A33,Data_Analitik!$AE$2:$AE$351,0)),"")) -> Rusak Berat Dominan | K33: Cara membaca threshold: • ≥ Minimum: nilai sama dengan atau di atas ambang. • ≤ Maksimum: nilai sama dengan atau di bawah ambang. • Untuk mencari ruas berkondisi rendah, Mantap/Baik biasanya dipakai dengan ≤ Maksimum. • Tidak Mantap/Rusak Ringan/Rusak Berat biasanya dipakai dengan ≥ Minimum. • Ranking selalu mengikuti nilai metrik aktif.
A34: =IF(ROW()-13<=$B$11,ROW()-13,"") -> 21 | B34: =IF(OR($A34="",$A34>SUM(Data_Analitik!$AD$2:$AD$351)),"",IFERROR(INDEX(Data_Analitik!$B$2:$B$351,MATCH($A34,Data_Analitik!$AE$2:$AE$351,0)),"")) -> 166 | C34: =IF(OR($A34="",$A34>SUM(Data_Analitik!$AD$2:$AD$351)),"",IFERROR(INDEX(Data_Analitik!$C$2:$C$351,MATCH($A34,Data_Analitik!$AE$2:$AE$351,0)),"")) -> Tambak Pipii - Batu Ampar | D34: =IF(OR($A34="",$A34>SUM(Data_Analitik!$AD$2:$AD$351)),"",IFERROR(INDEX(Data_Analitik!$D$2:$D$351,MATCH($A34,Data_Analitik!$AE$2:$AE$351,0)),"")) -> Padang Batung | E34: =IF(OR($A34="",$A34>SUM(Data_Analitik!$AD$2:$AD$351)),"",IFERROR(INDEX(Data_Analitik!$E$2:$E$351,MATCH($A34,Data_Analitik!$AE$2:$AE$351,0)),"")) -> 1.98 | F34: =IF(OR($A34="",$A34>SUM(Data_Analitik!$AD$2:$AD$351)),"",IFERROR(INDEX(Data_Analitik!$Z$2:$Z$351,MATCH($A34,Data_Analitik!$AE$2:$AE$351,0)),"")) -> 1 | G34: =IF(OR($A34="",$A34>SUM(Data_Analitik!$AD$2:$AD$351)),"",IFERROR(INDEX(Data_Analitik!$AA$2:$AA$351,MATCH($A34,Data_Analitik!$AE$2:$AE$351,0)),"")) -> 1 | H34: =IF(OR($A34="",$A34>SUM(Data_Analitik!$AD$2:$AD$351)),"",IFERROR(INDEX(Data_Analitik!$U$2:$U$351,MATCH($A34,Data_Analitik!$AE$2:$AE$351,0)),"")) -> 1.98 | I34: =IF(OR($A34="",$A34>SUM(Data_Analitik!$AD$2:$AD$351)),"",IFERROR(INDEX(Data_Analitik!$AB$2:$AB$351,MATCH($A34,Data_Analitik!$AE$2:$AE$351,0)),"")) -> Rusak Berat Dominan
A35: =IF(ROW()-13<=$B$11,ROW()-13,"") -> 22 | B35: =IF(OR($A35="",$A35>SUM(Data_Analitik!$AD$2:$AD$351)),"",IFERROR(INDEX(Data_Analitik!$B$2:$B$351,MATCH($A35,Data_Analitik!$AE$2:$AE$351,0)),"")) -> 129 | C35: =IF(OR($A35="",$A35>SUM(Data_Analitik!$AD$2:$AD$351)),"",IFERROR(INDEX(Data_Analitik!$C$2:$C$351,MATCH($A35,Data_Analitik!$AE$2:$AE$351,0)),"")) -> Batang Kulur Kanan - Bumi Berkat (Jl. Kisung) | D35: =IF(OR($A35="",$A35>SUM(Data_Analitik!$AD$2:$AD$351)),"",IFERROR(INDEX(Data_Analitik!$D$2:$D$351,MATCH($A35,Data_Analitik!$AE$2:$AE$351,0)),"")) -> Sungai Raya | E35: =IF(OR($A35="",$A35>SUM(Data_Analitik!$AD$2:$AD$351)),"",IFERROR(INDEX(Data_Analitik!$E$2:$E$351,MATCH($A35,Data_Analitik!$AE$2:$AE$351,0)),"")) -> 1.61 | F35: =IF(OR($A35="",$A35>SUM(Data_Analitik!$AD$2:$AD$351)),"",IFERROR(INDEX(Data_Analitik!$Z$2:$Z$351,MATCH($A35,Data_Analitik!$AE$2:$AE$351,0)),"")) -> 1 | G35: =IF(OR($A35="",$A35>SUM(Data_Analitik!$AD$2:$AD$351)),"",IFERROR(INDEX(Data_Analitik!$AA$2:$AA$351,MATCH($A35,Data_Analitik!$AE$2:$AE$351,0)),"")) -> 1 | H35: =IF(OR($A35="",$A35>SUM(Data_Analitik!$AD$2:$AD$351)),"",IFERROR(INDEX(Data_Analitik!$U$2:$U$351,MATCH($A35,Data_Analitik!$AE$2:$AE$351,0)),"")) -> 1.61 | I35: =IF(OR($A35="",$A35>SUM(Data_Analitik!$AD$2:$AD$351)),"",IFERROR(INDEX(Data_Analitik!$AB$2:$AB$351,MATCH($A35,Data_Analitik!$AE$2:$AE$351,0)),"")) -> Rusak Berat Dominan
A36: =IF(ROW()-13<=$B$11,ROW()-13,"") -> 23 | B36: =IF(OR($A36="",$A36>SUM(Data_Analitik!$AD$2:$AD$351)),"",IFERROR(INDEX(Data_Analitik!$B$2:$B$351,MATCH($A36,Data_Analitik!$AE$2:$AE$351,0)),"")) -> 300 | C36: =IF(OR($A36="",$A36>SUM(Data_Analitik!$AD$2:$AD$351)),"",IFERROR(INDEX(Data_Analitik!$C$2:$C$351,MATCH($A36,Data_Analitik!$AE$2:$AE$351,0)),"")) -> Jl. Tambangan - Ds. Baruh Jaya | D36: =IF(OR($A36="",$A36>SUM(Data_Analitik!$AD$2:$AD$351)),"",IFERROR(INDEX(Data_Analitik!$D$2:$D$351,MATCH($A36,Data_Analitik!$AE$2:$AE$351,0)),"")) -> Daha Selatan - Daha Utara | E36: =IF(OR($A36="",$A36>SUM(Data_Analitik!$AD$2:$AD$351)),"",IFERROR(INDEX(Data_Analitik!$E$2:$E$351,MATCH($A36,Data_Analitik!$AE$2:$AE$351,0)),"")) -> 2.23 | F36: =IF(OR($A36="",$A36>SUM(Data_Analitik!$AD$2:$AD$351)),"",IFERROR(INDEX(Data_Analitik!$Z$2:$Z$351,MATCH($A36,Data_Analitik!$AE$2:$AE$351,0)),"")) -> 1 | G36: =IF(OR($A36="",$A36>SUM(Data_Analitik!$AD$2:$AD$351)),"",IFERROR(INDEX(Data_Analitik!$AA$2:$AA$351,MATCH($A36,Data_Analitik!$AE$2:$AE$351,0)),"")) -> 0.88699553 | H36: =IF(OR($A36="",$A36>SUM(Data_Analitik!$AD$2:$AD$351)),"",IFERROR(INDEX(Data_Analitik!$U$2:$U$351,MATCH($A36,Data_Analitik!$AE$2:$AE$351,0)),"")) -> 1.6 | I36: =IF(OR($A36="",$A36>SUM(Data_Analitik!$AD$2:$AD$351)),"",IFERROR(INDEX(Data_Analitik!$AB$2:$AB$351,MATCH($A36,Data_Analitik!$AE$2:$AE$351,0)),"")) -> Rusak Berat Dominan
A37: =IF(ROW()-13<=$B$11,ROW()-13,"") -> 24 | B37: =IF(OR($A37="",$A37>SUM(Data_Analitik!$AD$2:$AD$351)),"",IFERROR(INDEX(Data_Analitik!$B$2:$B$351,MATCH($A37,Data_Analitik!$AE$2:$AE$351,0)),"")) -> 226 | C37: =IF(OR($A37="",$A37>SUM(Data_Analitik!$AD$2:$AD$351)),"",IFERROR(INDEX(Data_Analitik!$C$2:$C$351,MATCH($A37,Data_Analitik!$AE$2:$AE$351,0)),"")) -> Jl. Guru H. Izim - Ds. Pantai Ulin | D37: =IF(OR($A37="",$A37>SUM(Data_Analitik!$AD$2:$AD$351)),"",IFERROR(INDEX(Data_Analitik!$D$2:$D$351,MATCH($A37,Data_Analitik!$AE$2:$AE$351,0)),"")) -> Simpur | E37: =IF(OR($A37="",$A37>SUM(Data_Analitik!$AD$2:$AD$351)),"",IFERROR(INDEX(Data_Analitik!$E$2:$E$351,MATCH($A37,Data_Analitik!$AE$2:$AE$351,0)),"")) -> 0.62 | F37: =IF(OR($A37="",$A37>SUM(Data_Analitik!$AD$2:$AD$351)),"",IFERROR(INDEX(Data_Analitik!$Z$2:$Z$351,MATCH($A37,Data_Analitik!$AE$2:$AE$351,0)),"")) -> 1 | G37: =IF(OR($A37="",$A37>SUM(Data_Analitik!$AD$2:$AD$351)),"",IFERROR(INDEX(Data_Analitik!$AA$2:$AA$351,MATCH($A37,Data_Analitik!$AE$2:$AE$351,0)),"")) -> 1 | H37: =IF(OR($A37="",$A37>SUM(Data_Analitik!$AD$2:$AD$351)),"",IFERROR(INDEX(Data_Analitik!$U$2:$U$351,MATCH($A37,Data_Analitik!$AE$2:$AE$351,0)),"")) -> 0.62 | I37: =IF(OR($A37="",$A37>SUM(Data_Analitik!$AD$2:$AD$351)),"",IFERROR(INDEX(Data_Analitik!$AB$2:$AB$351,MATCH($A37,Data_Analitik!$AE$2:$AE$351,0)),"")) -> Rusak Berat Dominan
A38: =IF(ROW()-13<=$B$11,ROW()-13,"") -> 25 | B38: =IF(OR($A38="",$A38>SUM(Data_Analitik!$AD$2:$AD$351)),"",IFERROR(INDEX(Data_Analitik!$B$2:$B$351,MATCH($A38,Data_Analitik!$AE$2:$AE$351,0)),"")) -> 308 | C38: =IF(OR($A38="",$A38>SUM(Data_Analitik!$AD$2:$AD$351)),"",IFERROR(INDEX(Data_Analitik!$C$2:$C$351,MATCH($A38,Data_Analitik!$AE$2:$AE$351,0)),"")) -> Jl. Sungai Bugundi | D38: =IF(OR($A38="",$A38>SUM(Data_Analitik!$AD$2:$AD$351)),"",IFERROR(INDEX(Data_Analitik!$D$2:$D$351,MATCH($A38,Data_Analitik!$AE$2:$AE$351,0)),"")) -> Daha Selatan | E38: =IF(OR($A38="",$A38>SUM(Data_Analitik!$AD$2:$AD$351)),"",IFERROR(INDEX(Data_Analitik!$E$2:$E$351,MATCH($A38,Data_Analitik!$AE$2:$AE$351,0)),"")) -> 0.31 | F38: =IF(OR($A38="",$A38>SUM(Data_Analitik!$AD$2:$AD$351)),"",IFERROR(INDEX(Data_Analitik!$Z$2:$Z$351,MATCH($A38,Data_Analitik!$AE$2:$AE$351,0)),"")) -> 1 | G38: =IF(OR($A38="",$A38>SUM(Data_Analitik!$AD$2:$AD$351)),"",IFERROR(INDEX(Data_Analitik!$AA$2:$AA$351,MATCH($A38,Data_Analitik!$AE$2:$AE$351,0)),"")) -> 0.6 | H38: =IF(OR($A38="",$A38>SUM(Data_Analitik!$AD$2:$AD$351)),"",IFERROR(INDEX(Data_Analitik!$U$2:$U$351,MATCH($A38,Data_Analitik!$AE$2:$AE$351,0)),"")) -> 0 | I38: =IF(OR($A38="",$A38>SUM(Data_Analitik!$AD$2:$AD$351)),"",IFERROR(INDEX(Data_Analitik!$AB$2:$AB$351,MATCH($A38,Data_Analitik!$AE$2:$AE$351,0)),"")) -> Tidak Mantap Tinggi
A39: =IF(ROW()-13<=$B$11,ROW()-13,"") -> 26 | B39: =IF(OR($A39="",$A39>SUM(Data_Analitik!$AD$2:$AD$351)),"",IFERROR(INDEX(Data_Analitik!$B$2:$B$351,MATCH($A39,Data_Analitik!$AE$2:$AE$351,0)),"")) -> 191 | C39: =IF(OR($A39="",$A39>SUM(Data_Analitik!$AD$2:$AD$351)),"",IFERROR(INDEX(Data_Analitik!$C$2:$C$351,MATCH($A39,Data_Analitik!$AE$2:$AE$351,0)),"")) -> Bamban (Tibung) - Martajiwa | D39: =IF(OR($A39="",$A39>SUM(Data_Analitik!$AD$2:$AD$351)),"",IFERROR(INDEX(Data_Analitik!$D$2:$D$351,MATCH($A39,Data_Analitik!$AE$2:$AE$351,0)),"")) -> Angkinang | E39: =IF(OR($A39="",$A39>SUM(Data_Analitik!$AD$2:$AD$351)),"",IFERROR(INDEX(Data_Analitik!$E$2:$E$351,MATCH($A39,Data_Analitik!$AE$2:$AE$351,0)),"")) -> 0.66 | F39: =IF(OR($A39="",$A39>SUM(Data_Analitik!$AD$2:$AD$351)),"",IFERROR(INDEX(Data_Analitik!$Z$2:$Z$351,MATCH($A39,Data_Analitik!$AE$2:$AE$351,0)),"")) -> 1 | G39: =IF(OR($A39="",$A39>SUM(Data_Analitik!$AD$2:$AD$351)),"",IFERROR(INDEX(Data_Analitik!$AA$2:$AA$351,MATCH($A39,Data_Analitik!$AE$2:$AE$351,0)),"")) -> 0.93939394 | H39: =IF(OR($A39="",$A39>SUM(Data_Analitik!$AD$2:$AD$351)),"",IFERROR(INDEX(Data_Analitik!$U$2:$U$351,MATCH($A39,Data_Analitik!$AE$2:$AE$351,0)),"")) -> 0.56 | I39: =IF(OR($A39="",$A39>SUM(Data_Analitik!$AD$2:$AD$351)),"",IFERROR(INDEX(Data_Analitik!$AB$2:$AB$351,MATCH($A39,Data_Analitik!$AE$2:$AE$351,0)),"")) -> Rusak Berat Dominan
A40: =IF(ROW()-13<=$B$11,ROW()-13,"") -> 27 | B40: =IF(OR($A40="",$A40>SUM(Data_Analitik!$AD$2:$AD$351)),"",IFERROR(INDEX(Data_Analitik!$B$2:$B$351,MATCH($A40,Data_Analitik!$AE$2:$AE$351,0)),"")) -> 187 | C40: =IF(OR($A40="",$A40>SUM(Data_Analitik!$AD$2:$AD$351)),"",IFERROR(INDEX(Data_Analitik!$C$2:$C$351,MATCH($A40,Data_Analitik!$AE$2:$AE$351,0)),"")) -> Jl. AMD - Ds. Lok Binuang | D40: =IF(OR($A40="",$A40>SUM(Data_Analitik!$AD$2:$AD$351)),"",IFERROR(INDEX(Data_Analitik!$D$2:$D$351,MATCH($A40,Data_Analitik!$AE$2:$AE$351,0)),"")) -> Angkinang | E40: =IF(OR($A40="",$A40>SUM(Data_Analitik!$AD$2:$AD$351)),"",IFERROR(INDEX(Data_Analitik!$E$2:$E$351,MATCH($A40,Data_Analitik!$AE$2:$AE$351,0)),"")) -> 1.57 | F40: =IF(OR($A40="",$A40>SUM(Data_Analitik!$AD$2:$AD$351)),"",IFERROR(INDEX(Data_Analitik!$Z$2:$Z$351,MATCH($A40,Data_Analitik!$AE$2:$AE$351,0)),"")) -> 1 | G40: =IF(OR($A40="",$A40>SUM(Data_Analitik!$AD$2:$AD$351)),"",IFERROR(INDEX(Data_Analitik!$AA$2:$AA$351,MATCH($A40,Data_Analitik!$AE$2:$AE$351,0)),"")) -> 1 | H40: =IF(OR($A40="",$A40>SUM(Data_Analitik!$AD$2:$AD$351)),"",IFERROR(INDEX(Data_Analitik!$U$2:$U$351,MATCH($A40,Data_Analitik!$AE$2:$AE$351,0)),"")) -> 1.57 | I40: =IF(OR($A40="",$A40>SUM(Data_Analitik!$AD$2:$AD$351)),"",IFERROR(INDEX(Data_Analitik!$AB$2:$AB$351,MATCH($A40,Data_Analitik!$AE$2:$AE$351,0)),"")) -> Rusak Berat Dominan
A41: =IF(ROW()-13<=$B$11,ROW()-13,"") -> 28 | B41: =IF(OR($A41="",$A41>SUM(Data_Analitik!$AD$2:$AD$351)),"",IFERROR(INDEX(Data_Analitik!$B$2:$B$351,MATCH($A41,Data_Analitik!$AE$2:$AE$351,0)),"")) -> 127 | C41: =IF(OR($A41="",$A41>SUM(Data_Analitik!$AD$2:$AD$351)),"",IFERROR(INDEX(Data_Analitik!$C$2:$C$351,MATCH($A41,Data_Analitik!$AE$2:$AE$351,0)),"")) -> Jarau - Parandakan | D41: =IF(OR($A41="",$A41>SUM(Data_Analitik!$AD$2:$AD$351)),"",IFERROR(INDEX(Data_Analitik!$D$2:$D$351,MATCH($A41,Data_Analitik!$AE$2:$AE$351,0)),"")) -> Sungai Raya | E41: =IF(OR($A41="",$A41>SUM(Data_Analitik!$AD$2:$AD$351)),"",IFERROR(INDEX(Data_Analitik!$E$2:$E$351,MATCH($A41,Data_Analitik!$AE$2:$AE$351,0)),"")) -> 0.7 | F41: =IF(OR($A41="",$A41>SUM(Data_Analitik!$AD$2:$AD$351)),"",IFERROR(INDEX(Data_Analitik!$Z$2:$Z$351,MATCH($A41,Data_Analitik!$AE$2:$AE$351,0)),"")) -> 1 | G41: =IF(OR($A41="",$A41>SUM(Data_Analitik!$AD$2:$AD$351)),"",IFERROR(INDEX(Data_Analitik!$AA$2:$AA$351,MATCH($A41,Data_Analitik!$AE$2:$AE$351,0)),"")) -> 0.88571429 | H41: =IF(OR($A41="",$A41>SUM(Data_Analitik!$AD$2:$AD$351)),"",IFERROR(INDEX(Data_Analitik!$U$2:$U$351,MATCH($A41,Data_Analitik!$AE$2:$AE$351,0)),"")) -> 0.5 | I41: =IF(OR($A41="",$A41>SUM(Data_Analitik!$AD$2:$AD$351)),"",IFERROR(INDEX(Data_Analitik!$AB$2:$AB$351,MATCH($A41,Data_Analitik!$AE$2:$AE$351,0)),"")) -> Rusak Berat Dominan
A42: =IF(ROW()-13<=$B$11,ROW()-13,"") -> 29 | B42: =IF(OR($A42="",$A42>SUM(Data_Analitik!$AD$2:$AD$351)),"",IFERROR(INDEX(Data_Analitik!$B$2:$B$351,MATCH($A42,Data_Analitik!$AE$2:$AE$351,0)),"")) -> 313 | C42: =IF(OR($A42="",$A42>SUM(Data_Analitik!$AD$2:$AD$351)),"",IFERROR(INDEX(Data_Analitik!$C$2:$C$351,MATCH($A42,Data_Analitik!$AE$2:$AE$351,0)),"")) -> Jl. Teluk Haur II | D42: =IF(OR($A42="",$A42>SUM(Data_Analitik!$AD$2:$AD$351)),"",IFERROR(INDEX(Data_Analitik!$D$2:$D$351,MATCH($A42,Data_Analitik!$AE$2:$AE$351,0)),"")) -> Daha Utara | E42: =IF(OR($A42="",$A42>SUM(Data_Analitik!$AD$2:$AD$351)),"",IFERROR(INDEX(Data_Analitik!$E$2:$E$351,MATCH($A42,Data_Analitik!$AE$2:$AE$351,0)),"")) -> 0.21 | F42: =IF(OR($A42="",$A42>SUM(Data_Analitik!$AD$2:$AD$351)),"",IFERROR(INDEX(Data_Analitik!$Z$2:$Z$351,MATCH($A42,Data_Analitik!$AE$2:$AE$351,0)),"")) -> 1 | G42: =IF(OR($A42="",$A42>SUM(Data_Analitik!$AD$2:$AD$351)),"",IFERROR(INDEX(Data_Analitik!$AA$2:$AA$351,MATCH($A42,Data_Analitik!$AE$2:$AE$351,0)),"")) -> 1 | H42: =IF(OR($A42="",$A42>SUM(Data_Analitik!$AD$2:$AD$351)),"",IFERROR(INDEX(Data_Analitik!$U$2:$U$351,MATCH($A42,Data_Analitik!$AE$2:$AE$351,0)),"")) -> 0.21 | I42: =IF(OR($A42="",$A42>SUM(Data_Analitik!$AD$2:$AD$351)),"",IFERROR(INDEX(Data_Analitik!$AB$2:$AB$351,MATCH($A42,Data_Analitik!$AE$2:$AE$351,0)),"")) -> Rusak Berat Dominan
A43: =IF(ROW()-13<=$B$11,ROW()-13,"") -> 30 | B43: =IF(OR($A43="",$A43>SUM(Data_Analitik!$AD$2:$AD$351)),"",IFERROR(INDEX(Data_Analitik!$B$2:$B$351,MATCH($A43,Data_Analitik!$AE$2:$AE$351,0)),"")) -> 278 | C43: =IF(OR($A43="",$A43>SUM(Data_Analitik!$AD$2:$AD$351)),"",IFERROR(INDEX(Data_Analitik!$C$2:$C$351,MATCH($A43,Data_Analitik!$AE$2:$AE$351,0)),"")) -> Jl. Bubuih (Ds. Halunuk) - Kandihin | D43: =IF(OR($A43="",$A43>SUM(Data_Analitik!$AD$2:$AD$351)),"",IFERROR(INDEX(Data_Analitik!$D$2:$D$351,MATCH($A43,Data_Analitik!$AE$2:$AE$351,0)),"")) -> Loksado | E43: =IF(OR($A43="",$A43>SUM(Data_Analitik!$AD$2:$AD$351)),"",IFERROR(INDEX(Data_Analitik!$E$2:$E$351,MATCH($A43,Data_Analitik!$AE$2:$AE$351,0)),"")) -> 2.93 | F43: =IF(OR($A43="",$A43>SUM(Data_Analitik!$AD$2:$AD$351)),"",IFERROR(INDEX(Data_Analitik!$Z$2:$Z$351,MATCH($A43,Data_Analitik!$AE$2:$AE$351,0)),"")) -> 1 | G43: =IF(OR($A43="",$A43>SUM(Data_Analitik!$AD$2:$AD$351)),"",IFERROR(INDEX(Data_Analitik!$AA$2:$AA$351,MATCH($A43,Data_Analitik!$AE$2:$AE$351,0)),"")) -> 0.69556314 | H43: =IF(OR($A43="",$A43>SUM(Data_Analitik!$AD$2:$AD$351)),"",IFERROR(INDEX(Data_Analitik!$U$2:$U$351,MATCH($A43,Data_Analitik!$AE$2:$AE$351,0)),"")) -> 0.69999999 | I43: =IF(OR($A43="",$A43>SUM(Data_Analitik!$AD$2:$AD$351)),"",IFERROR(INDEX(Data_Analitik!$AB$2:$AB$351,MATCH($A43,Data_Analitik!$AE$2:$AE$351,0)),"")) -> Rusak Berat Dominan
A44: =IF(ROW()-13<=$B$11,ROW()-13,"") -> 31 | B44: =IF(OR($A44="",$A44>SUM(Data_Analitik!$AD$2:$AD$351)),"",IFERROR(INDEX(Data_Analitik!$B$2:$B$351,MATCH($A44,Data_Analitik!$AE$2:$AE$351,0)),"")) -> 015 | C44: =IF(OR($A44="",$A44>SUM(Data_Analitik!$AD$2:$AD$351)),"",IFERROR(INDEX(Data_Analitik!$C$2:$C$351,MATCH($A44,Data_Analitik!$AE$2:$AE$351,0)),"")) -> Jl. Dahlia | D44: =IF(OR($A44="",$A44>SUM(Data_Analitik!$AD$2:$AD$351)),"",IFERROR(INDEX(Data_Analitik!$D$2:$D$351,MATCH($A44,Data_Analitik!$AE$2:$AE$351,0)),"")) -> Kandangan | E44: =IF(OR($A44="",$A44>SUM(Data_Analitik!$AD$2:$AD$351)),"",IFERROR(INDEX(Data_Analitik!$E$2:$E$351,MATCH($A44,Data_Analitik!$AE$2:$AE$351,0)),"")) -> 0.18 | F44: =IF(OR($A44="",$A44>SUM(Data_Analitik!$AD$2:$AD$351)),"",IFERROR(INDEX(Data_Analitik!$Z$2:$Z$351,MATCH($A44,Data_Analitik!$AE$2:$AE$351,0)),"")) -> 1 | G44: =IF(OR($A44="",$A44>SUM(Data_Analitik!$AD$2:$AD$351)),"",IFERROR(INDEX(Data_Analitik!$AA$2:$AA$351,MATCH($A44,Data_Analitik!$AE$2:$AE$351,0)),"")) -> 0.77777777 | H44: =IF(OR($A44="",$A44>SUM(Data_Analitik!$AD$2:$AD$351)),"",IFERROR(INDEX(Data_Analitik!$U$2:$U$351,MATCH($A44,Data_Analitik!$AE$2:$AE$351,0)),"")) -> 0.079999998 | I44: =IF(OR($A44="",$A44>SUM(Data_Analitik!$AD$2:$AD$351)),"",IFERROR(INDEX(Data_Analitik!$AB$2:$AB$351,MATCH($A44,Data_Analitik!$AE$2:$AE$351,0)),"")) -> Rusak Berat Dominan
